Workbook
Name NewFile: GtoPdb!$A$1:$P$400

Sheet INFO
A1: Tab | B1: Description
A2: Metadata | B2: Metadata for the datasets imported to GproteinDb.
A3: Bouvier-GEMTA | B3: Data imported into GproteinDb. See GproteinDb's documentation or Table 1 in the GproteinDb 2024 article in Nucleic Acids Research.
A4: Inoue-NanoBiT-G | B4: Data imported into GproteinDb. See GproteinDb's documentation or Table 1 in the GproteinDb 2024 article in Nucleic Acids Research.
A5: Inoue-TGFa | B5: Data imported into GproteinDb. See GproteinDb's documentation or Table 1 in the GproteinDb 2024 article in Nucleic Acids Research.
A6: Lambert-RGB-GDP_wLig | B6: Data imported into GproteinDb. See GproteinDb's documentation or Table 1 in the GproteinDb 2024 article in Nucleic Acids Research.
A7: Lambert-RGB-GDP_woLig | B7: Data imported into GproteinDb. See GproteinDb's documentation or Table 1 in the GproteinDb 2024 article in Nucleic Acids Research.
A8: Martemyanov-FreeGby-Nluc | B8: Data imported into GproteinDb. See GproteinDb's documentation or Table 1 in the GproteinDb 2024 article in Nucleic Acids Research.
A9: Roth-TRUPATH | B9: Data imported into GproteinDb. See GproteinDb's documentation or Table 1 in the GproteinDb 2024 article in Nucleic Acids Research.
A10: Fig4a-Gq | B10: Intersection of Gq couplings from the Bouvier GEMTA, Inoue TGFa and Martemyanov FREEBG datasets. Used for Fig. 4 in the GproteinDb 2024 article in Nucleic Acids Research.
A11: Fig4b-Econst | B11: Constitutive vs. agonist-induced coupling agreement on primary transducer (Lambert RGB-GDP dataset). Used for Fig. 4 in the GproteinDb 2024 article in Nucleic Acids Research.
A12: Fig4c_CouplComp | B12: Primary transducer agreement across the GtoPdb, Bouvier GEMTA and Martemyanov FREEBG-Nluc datasets. Used for Fig. 4 in the GproteinDb 2024 article in Nucleic Acids Research.
... A16: GtoPdb | B16: Couplings from the Guide to Pharmacology database. Not imported from this tab, but directly from that database.
A18: Only the Bouvier-GEMTA data set has arrestin data (columns: β1/GRK, β1, β2/GRK)

Sheet Metadata
A1: Tab | B1: Biosensor | C1: Parameter | D1: Down- stream steps | E1: _
A2: Bouvier-GEMTA | B2: GEMTA | C2: log(Emax/EC50) | D2: 3
A3: Inoue-NanoBiT-G | B3: NanoBiT-G | C3: log(Emax/EC50) | D3: 1
A4: Inoue-TGFa | B4: TGF𝛼 | C4: log(Emax/EC50) | D4: 5
A5: Lambert-RGB-GDP_Efficacy | B5: RGB-GDP | C5: Efficacy | D5: 0
A6: Lambert-RGB-GDP_Econst | B6: RGB-GDP | C6: Econstitutive | D6: 0
A7: Martemyanov-FreeGβγ-Nluc | B7: FreeGβγ-Nluc | C7: Activation rate (s-1) | D7: 2
A8: Roth-TRUPATH | B8: TRUPATH | C8: log(Emax/EC50) | D8: 1
B11: Gβγ

Sheet Bouvier-GEMTA
A1: Receptor (UniProt) | B1: DOI | C1: Ligand ID type | D1: Ligand ID | E1: Phys/ Surr | F1: Supp Gs fam | G1: Supp Gi/o fam | H1: Supp Gq/11 fam | I1: Supp G12/13 fam | J1: #Fam | K1: Primary (1') fam | L1: Rank Gs fam | M1: Rank Gi/o fam | N1: Rank Gq/11 fam | O1: Rank G12/13 fam | P1: % of 1' family GsFam | Q1: % of 1' family Gi/oFam | R1: % of 1' family Gq/11Fam | S1: % of 1' family G12/13Fam | T1: Gs-fam | U1: Gi/o-fam | V1: Gq/11-fam | W1: G12/13-fam | X1: Primary (1') subtype | Y1: % of 1' subtype GsL | Z1: % of 1' subtype Gi1 | AA1: % of 1' subtype Gi2 | AB1: % of 1' subtype GoA | AC1: % of 1' subtype GoB | AD1: % of 1' subtype Gz | AE1: % of 1' subtype Gq | AF1: % of 1' subtype G11 | AG1: % of 1' subtype G14 | AH1: % of 1' subtype G15 | AI1: % of 1' subtype G12 | AJ1: % of 1' subtype G13 | AK1: GsL | AL1: Gi1 | AM1: Gi2 | AN1: GoA | AO1: GoB | AP1: Gz | AQ1: Gq | AR1: G11 | AS1: G14 | AT1: G15 | AU1: G12 | AV1: G13 | AW1: β1/ GRK2 | AX1: β2 | AY1: β2/ GRK2 | AZ1: Emax GsL | BA1: Emax Gi1 | BB1: Emax Gi2 | BC1: Emax GoA | BD1: Emax GoB | BE1: Emax Gz | BF1: Emax Gq | BG1: Emax G11 | BH1: Emax G14 | BI1: Emax G15 | BJ1: Emax G12 | BK1: Emax G13 | BL1: Emax β1/GRK2 | BM1: Emax β2 | BN1: Emax β2/GRK2 | BO1: Emax GsL | BP1: Emax Gi1 | BQ1: Emax Gi2 | BR1: Emax GoA | BS1: Emax GoA | BT1: Emax Gz | BU1: Emax Gq | BV1: Emax G11 | BW1: Emax G14 | BX1: Emax G15 | BY1: Emax G12 | BZ1: Emax G13 | CA1: Emax βarr1 /GRK2 | CB1: Emax βarr2 | CC1: Emax βarr2 /GRK2 | CD1: pEC50 GsL | CE1: pEC50 Gi1 | CF1: pEC50 Gi2 | CG1: pEC50 GoA | CH1: pEC50 GoB | CI1: pEC50 Gz | CJ1: pEC50 Gq | CK1: pEC50 G11 | CL1: pEC50 G14 | CM1: pEC50 G15 | CN1: pEC50 G12 | CO1: pEC50 G13 | CP1: pEC50 β1/GRK2 | CQ1: pEC50 β2 | CR1: pEC50 β2/GRK2 | CS1: Ligand short (author) | CT1: Ligand long (author) | CU1: Basal SD GsSL | CV1: Basal SD Gi1 | CW1: Basal SD Gi2 | CX1: Basal SD GoA | CY1: Basal SD GoB | CZ1: Basal SD Gz | DA1: Basal SD Gq | DB1: Basal SD G11 | DC1: Basal SD G14 | DD1: Basal SD G15 | DE1: Basal SD G12 | DF1: Basal SD G13 | DG1: Basal SD βarr1 /GRK2 | DH1: Basal SD βarr2 | DI1: Basal SD βarr2 /GRK2 | DJ1: #SDs GsL | DK1: #SDs Gi1 | DL1: #SDs Gi2 | DM1: #SDs GoA | DN1: #SDs GoB | DO1: #SDs Gz | DP1: #SDs Gq | DQ1: #SDs G11 | DR1: #SDs G14 | DS1: #SDs G15 | DT1: #SDs G12 | DU1: #SDs G13 | DV1: #SDs β2 | DW1: #SDs β1/GRK2 | DX1: #SDs β2/GRK2
A2: ACM3 | B2: 10.7554/eLife.74101 | C2: =IF(VLOOKUP($A2,'B-Ligands'!$A:$G,5,FALSE)="","",VLOOKUP($A2,'B-Ligands'!$A:$G,5,FALSE)) -> Guide To Pharmacology | D2: =IF(VLOOKUP($A2,'B-Ligands'!$A:$G,6,FALSE)="","",VLOOKUP($A2,'B-Ligands'!$A:$G,6,FALSE)) -> 294 | E2: =IF(VLOOKUP($A2,'B-Ligands'!$A:$G,7,FALSE)="","",VLOOKUP($A2,'B-Ligands'!$A:$G,7,FALSE)) -> Phys | F2: =IF(T2>0,1,"") | G2: =IF(U2>0,1,"") -> 1 | H2: =IF(V2>0,1,"") -> 1 | I2: =IF(W2>0,1,"") | J2: =COUNTIF(L2:O2,">0") -> 2 | K2: =SUBSTITUTE(INDEX(T$1:W$1,1,MATCH(MAX(T2:W2),T2:W2,0)),"-fam","") -> Gq/11 | L2: =IF(T2=0,0,_xlfn.RANK.EQ(T2,$T2:$W2,0)) -> 0 | M2: =IF(U2=0,0,_xlfn.RANK.EQ(U2,$T2:$W2,0)) -> 2 | N2: =IF(V2=0,0,_xlfn.RANK.EQ(V2,$T2:$W2,0)) -> 1 | O2: =IF(W2=0,0,_xlfn.RANK.EQ(W2,$T2:$W2,0)) -> 0 | P2: =T2/MAX($T2:$W2)*100 -> 0 | Q2: =U2/MAX($T2:$W2)*100 -> 71.863004 | R2: =V2/MAX($T2:$W2)*100 -> 100 | S2: =W2/MAX($T2:$W2)*100 -> 0 | T2: =AK2 -> 0 | U2: =MAX(AL2:AP2) -> 5.4328431 | V2: =MAX(AQ2:AT2) -> 7.56 | W2: =MAX(AU2:AV2) -> 0 | X2: =INDEX(AK$1:AV$1,1,MATCH(MAX(AK2:AV2),AK2:AV2,0)) -> G15 | Y2: =AK2/MAX($AK2:$AV2)*100 -> 0 | Z2: =AL2/MAX($AK2:$AV2)*100 -> 71.863004 | AA2: =AM2/MAX($AK2:$AV2)*100 -> 65.307423 | AB2: =AN2/MAX($AK2:$AV2)*100 -> 66.618228 | AC2: =AO2/MAX($AK2:$AV2)*100 -> 68.814588 | AD2: =AP2/MAX($AK2:$AV2)*100 -> 67.265199 | AE2: =AQ2/MAX($AK2:$AV2)*100 -> 93.767713 | AF2: =AR2/MAX($AK2:$AV2)*100 -> 97.379297 | ... AJ2: =AV2/MAX($AK2:$AV2)*100 -> 0 | AK2: {=_xlfn.IFS(AZ2=0,0,AZ2>0,(LOG(0.01*AZ2/10^-CD2)))} -> 0 | AL2: {=_xlfn.IFS(BA2=0,0,BA2>0,(LOG(0.01*BA2/10^-CE2)))} -> 5.4328431 | AM2: {=_xlfn.IFS(BB2=0,0,BB2>0,(LOG(0.01*BB2/10^-CF2)))} -> 4.9372411 | AN2: {=_xlfn.IFS(BC2=0,0,BC2>0,(LOG(0.01*BC2/10^-CG2)))} -> 5.0363381 | AO2: {=_xlfn.IFS(BD2=0,0,BD2>0,(LOG(0.01*BD2/10^-CH2)))} -> 5.2023828 | AP2: {=_xlfn.IFS(BE2=0,0,BE2>0,(LOG(0.01*BE2/10^-CI2)))} -> 5.085249 | AQ2: {=_xlfn.IFS(BF2=0,0,BF2>0,(LOG(0.01*BF2/10^-CJ2)))} -> 7.0888391 | AR2: {=_xlfn.IFS(BG2=0,0,BG2>0,(LOG(0.01*BG2/10^-CK2)))} -> 7.3618749 | ... AY2: {=_xlfn.IFS(BN2=0,0,BN2>0,(LOG(0.01*BN2/10^-CR2)))} -> 4.7417893 | AZ2: =IF(BO2="",0,100*BO2/MAX(BO:BO)) -> 0 | BA2: =IF(BP2="",0,100*BP2/MAX($BP:$BT)) -> 36.294691 | BB2: =IF(BQ2="",0,100*BQ2/MAX($BP:$BT)) -> 12.654388 | BC2: =IF(BR2="",0,100*BR2/MAX($BP:$BT)) -> 12.004334 | BD2: =IF(BS2="",0,100*BS2/MAX($BP:$BT)) -> 17.963164 | BE2: =IF(BT2="",0,100*BT2/MAX($BP:$BT)) -> 12.860238 | BF2: =IF(BU2="",0,100*BU2/MAX($BU:$BX)) -> 57.788191 | BG2: =IF(BV2="",0,100*BV2/MAX($BU:$BX)) -> 72.089972 | BH2: =IF(BW2="",0,100*BW2/MAX($BU:$BX)) -> 86.60731 | BI2: =IF(BX2="",0,100*BX2/MAX($BU:$BX)) -> 100 | BJ2: =IF(BY2="",0,100*BY2/MAX($BY:$BZ)) -> 0 | BK2: =IF(BZ2="",0,100*BZ2/MAX($BY:$BZ)) -> 0 | BL2: =IF(CA2="",0,100*CA2/MAX($CA:$CC)) -> 1.2047667 | BM2: =IF(CB2="",0,100*CB2/MAX($CA:$CC)) -> 2.1554213 | BN2: =IF(CC2="",0,100*CC2/MAX($CA:$CC)) -> 7.2910373 | BP2: 335 | BQ2: 116.8 | BR2: 110.8 | BS2: 165.8 | BT2: 118.7 | BU2: 616.6 | BV2: 769.2 | BW2: 924.1 | BX2: 1067 | CA2: 35.89 | CB2: 64.21 | CC2: 217.2 | CE2: 5.873 | CF2: 5.835 | CG2: 5.957 | CH2: 5.948 | CI2: 5.976 | CJ2: 7.327 | CK2: 7.504 | CL2: 7.366 | CM2: 7.56 | CP2: 6.365 | CQ2: 5.433 | CR2: 5.879 | CS2: =IF(VLOOKUP($A2,'B-Ligands'!$A:$G,3,FALSE)="","",VLOOKUP($A2,'B-Ligands'!$A:$G,3,FALSE)) | CT2: =IF(VLOOKUP($A2,'B-Ligands'!$A:$G,4,FALSE)="","",VLOOKUP($A2,'B-Ligands'!$A:$G,4,FALSE)) -> Acetylcholine | CU2: 19.695659 | CV2: 8.5807007 | CW2: 7.7895008 | CX2: 8.964211 | CY2: 7.9233674 | CZ2: 6.6408931 | DA2: 11.893188 | DB2: 8.7721913 | DC2: 11.108603 | DD2: 16.947394 | DE2: 11.491137 | DF2: 2.7470645 | DG2: 9.7321937 | DH2: 8.4345414 | DI2: 2.7535127 | DJ2: =IF(BO2="",0,BO2/CU2) -> 0 | DK2: =IF(BP2="",0,BP2/CV2) -> 39.041101 | DL2: =IF(BQ2="",0,BQ2/CW2) -> 14.994542 | DM2: =IF(BR2="",0,BR2/CX2) -> 12.360262 | DN2: =IF(BS2="",0,BS2/CY2) -> 20.925447 | DO2: =IF(BT2="",0,BT2/CZ2) -> 17.874102 | DP2: =IF(BU2="",0,BU2/DA2) -> 51.844803 | DQ2: =IF(BV2="",0,BV2/DB2) -> 87.686186 | ... DX2: =IF(CC2="",0,CC2/DI2) -> 78.881061
A3: BKRB2 | B3: 10.7554/eLife.74101 | C3: =IF(VLOOKUP($A3,'B-Ligands'!$A:$G,5,FALSE)="","",VLOOKUP($A3,'B-Ligands'!$A:$G,5,FALSE)) -> Guide To Pharmacology | D3: =IF(VLOOKUP($A3,'B-Ligands'!$A:$G,6,FALSE)="","",VLOOKUP($A3,'B-Ligands'!$A:$G,6,FALSE)) -> 650 | E3: =IF(VLOOKUP($A3,'B-Ligands'!$A:$G,7,FALSE)="","",VLOOKUP($A3,'B-Ligands'!$A:$G,7,FALSE)) -> Phys | F3: =IF(T3>0,1,"") | G3: =IF(U3>0,1,"") -> 1 | H3: =IF(V3>0,1,"") -> 1 | I3: =IF(W3>0,1,"") -> 1 | J3: =COUNTIF(L3:O3,">0") -> 3 | K3: =SUBSTITUTE(INDEX(T$1:W$1,1,MATCH(MAX(T3:W3),T3:W3,0)),"-fam","") -> Gq/11 | L3: =IF(T3=0,0,_xlfn.RANK.EQ(T3,$T3:$W3,0)) -> 0 | M3: =IF(U3=0,0,_xlfn.RANK.EQ(U3,$T3:$W3,0)) -> 3 | N3: =IF(V3=0,0,_xlfn.RANK.EQ(V3,$T3:$W3,0)) -> 1 | O3: =IF(W3=0,0,_xlfn.RANK.EQ(W3,$T3:$W3,0)) -> 2 | P3: =T3/MAX($T3:$W3)*100 -> 0 | Q3: =U3/MAX($T3:$W3)*100 -> 84.611569 | R3: =V3/MAX($T3:$W3)*100 -> 100 | S3: =W3/MAX($T3:$W3)*100 -> 97.715007 | T3: =AK3 -> 0 | U3: =MAX(AL3:AP3) -> 7.9932155 | V3: =MAX(AQ3:AT3) -> 9.4469534 | W3: =MAX(AU3:AV3) -> 9.2310912 | X3: =INDEX(AK$1:AV$1,1,MATCH(MAX(AK3:AV3),AK3:AV3,0)) -> G14 | Y3: =AK3/MAX($AK3:$AV3)*100 -> 0 | Z3: =AL3/MAX($AK3:$AV3)*100 -> 83.172064 | AA3: =AM3/MAX($AK3:$AV3)*100 -> 77.443689 | AB3: =AN3/MAX($AK3:$AV3)*100 -> 74.528715 | AC3: =AO3/MAX($AK3:$AV3)*100 -> 81.798461 | AD3: =AP3/MAX($AK3:$AV3)*100 -> 84.611569 | AE3: =AQ3/MAX($AK3:$AV3)*100 -> 99.993437 | AF3: =AR3/MAX($AK3:$AV3)*100 -> 99.690754 | ... AJ3: =AV3/MAX($AK3:$AV3)*100 -> 95.204424 | AK3: {=_xlfn.IFS(AZ3=0,0,AZ3>0,(LOG(0.01*AZ3/10^-CD3)))} -> 0 | AL3: {=_xlfn.IFS(BA3=0,0,BA3>0,(LOG(0.01*BA3/10^-CE3)))} -> 7.8572262 | AM3: {=_xlfn.IFS(BB3=0,0,BB3>0,(LOG(0.01*BB3/10^-CF3)))} -> 7.3160693 | AN3: {=_xlfn.IFS(BC3=0,0,BC3>0,(LOG(0.01*BC3/10^-CG3)))} -> 7.040693 | AO3: {=_xlfn.IFS(BD3=0,0,BD3>0,(LOG(0.01*BD3/10^-CH3)))} -> 7.7274626 | AP3: {=_xlfn.IFS(BE3=0,0,BE3>0,(LOG(0.01*BE3/10^-CI3)))} -> 7.9932155 | AQ3: {=_xlfn.IFS(BF3=0,0,BF3>0,(LOG(0.01*BF3/10^-CJ3)))} -> 9.4463335 | AR3: {=_xlfn.IFS(BG3=0,0,BG3>0,(LOG(0.01*BG3/10^-CK3)))} -> 9.4177391 | ... AY3: {=_xlfn.IFS(BN3=0,0,BN3>0,(LOG(0.01*BN3/10^-CR3)))} -> 8.1178115 | AZ3: =IF(BO3="",0,100*BO3/MAX(BO:BO)) -> 0 | BA3: =IF(BP3="",0,100*BP3/MAX($BP:$BT)) -> 51.787649 | BB3: =IF(BQ3="",0,100*BQ3/MAX($BP:$BT)) -> 27.865655 | BC3: =IF(BR3="",0,100*BR3/MAX($BP:$BT)) -> 16.132178 | BD3: =IF(BS3="",0,100*BS3/MAX($BP:$BT)) -> 39.035753 | BE3: =IF(BT3="",0,100*BT3/MAX($BP:$BT)) -> 22.091008 | BF3: =IF(BU3="",0,100*BU3/MAX($BU:$BX)) -> 53.992502 | BG3: =IF(BV3="",0,100*BV3/MAX($BU:$BX)) -> 75.117151 | BH3: =IF(BW3="",0,100*BW3/MAX($BU:$BX)) -> 81.649485 | BI3: =IF(BX3="",0,100*BX3/MAX($BU:$BX)) -> 98.313027 | BJ3: =IF(BY3="",0,100*BY3/MAX($BY:$BZ)) -> 11.778533 | BK3: =IF(BZ3="",0,100*BZ3/MAX($BY:$BZ)) -> 68.535826 | BL3: =IF(CA3="",0,100*CA3/MAX($CA:$CC)) -> 58.308157 | BM3: =IF(CB3="",0,100*CB3/MAX($CA:$CC)) -> 29.832158 | BN3: =IF(CC3="",0,100*CC3/MAX($CA:$CC)) -> 39.610608 | BP3: 478 | BQ3: 257.2 | BR3: 148.9 | BS3: 360.3 | BT3: 203.9 | BU3: 576.1 | BV3: 801.5 | BW3: 871.2 | BX3: 1049 | BY3: 83.18 | BZ3: 484 | CA3: 1737 | CB3: 888.7 | CC3: 1180 | CE3: 8.143 | CF3: 7.871 | CG3: 7.833 | CH3: 8.136 | CI3: 8.649 | CJ3: 9.714 | CK3: 9.542 | CL3: 9.535 | CM3: 8.754 | CN3: 10.16 | CO3: 9.158 | CP3: 8.622 | CQ3: 8.535 | CR3: 8.52 | CS3: =IF(VLOOKUP($A3,'B-Ligands'!$A:$G,3,FALSE)="","",VLOOKUP($A3,'B-Ligands'!$A:$G,3,FALSE)) | CT3: =IF(VLOOKUP($A3,'B-Ligands'!$A:$G,4,FALSE)="","",VLOOKUP($A3,'B-Ligands'!$A:$G,4,FALSE)) -> Kallidin | CU3: 19.117169 | CV3: 32.15434 | CW3: 28.669608 | CX3: 26.28411 | CY3: 26.746392 | CZ3: 18.744433 | DA3: 4.437505 | DB3: 21.933326 | DC3: 12.624713 | DD3: 12.18455 | DE3: 8.9232861 | DF3: 10.584937 | DG3: 23.230597 | DH3: 13.492497 | DI3: 21.537564 | DJ3: =IF(BO3="",0,BO3/CU3) -> 0 | DK3: =IF(BP3="",0,BP3/CV3) -> 14.8658 | DL3: =IF(BQ3="",0,BQ3/CW3) -> 8.9711726 | DM3: =IF(BR3="",0,BR3/CX3) -> 5.6650196 | DN3: =IF(BS3="",0,BS3/CY3) -> 13.470976 | DO3: =IF(BT3="",0,BT3/CZ3) -> 10.877896 | DP3: =IF(BU3="",0,BU3/DA3) -> 129.8252 | DQ3: =IF(BV3="",0,BV3/DB3) -> 36.542565 | ... DX3: =IF(CC3="",0,CC3/DI3) -> 54.787997
A4: ADA1A | B4: 10.7554/eLife.74101 | C4: =IF(VLOOKUP($A4,'B-Ligands'!$A:$G,5,FALSE)="","",VLOOKUP($A4,'B-Ligands'!$A:$G,5,FALSE)) -> Guide To Pharmacology | D4: =IF(VLOOKUP($A4,'B-Ligands'!$A:$G,6,FALSE)="","",VLOOKUP($A4,'B-Ligands'!$A:$G,6,FALSE)) -> 484 | E4: =IF(VLOOKUP($A4,'B-Ligands'!$A:$G,7,FALSE)="","",VLOOKUP($A4,'B-Ligands'!$A:$G,7,FALSE)) -> Phys | F4: =IF(T4>0,1,"") -> 1 | G4: =IF(U4>0,1,"") -> 1 | H4: =IF(V4>0,1,"") -> 1 | I4: =IF(W4>0,1,"") | J4: =COUNTIF(L4:O4,">0") -> 3 | K4: =SUBSTITUTE(INDEX(T$1:W$1,1,MATCH(MAX(T4:W4),T4:W4,0)),"-fam","") -> Gq/11 | L4: =IF(T4=0,0,_xlfn.RANK.EQ(T4,$T4:$W4,0)) -> 2 | M4: =IF(U4=0,0,_xlfn.RANK.EQ(U4,$T4:$W4,0)) -> 3 | N4: =IF(V4=0,0,_xlfn.RANK.EQ(V4,$T4:$W4,0)) -> 1 | O4: =IF(W4=0,0,_xlfn.RANK.EQ(W4,$T4:$W4,0)) -> 0 | P4: =T4/MAX($T4:$W4)*100 -> 84.643002 | Q4: =U4/MAX($T4:$W4)*100 -> 77.877047 | R4: =V4/MAX($T4:$W4)*100 -> 100 | S4: =W4/MAX($T4:$W4)*100 -> 0 | T4: =AK4 -> 6.5774968 | U4: =MAX(AL4:AP4) -> 6.0517233 | V4: =MAX(AQ4:AT4) -> 7.7708689 | W4: =MAX(AU4:AV4) -> 0 | X4: =INDEX(AK$1:AV$1,1,MATCH(MAX(AK4:AV4),AK4:AV4,0)) -> G15 | Y4: =AK4/MAX($AK4:$AV4)*100 -> 84.643002 | Z4: =AL4/MAX($AK4:$AV4)*100 -> 75.908979 | AA4: =AM4/MAX($AK4:$AV4)*100 -> 0 | AB4: =AN4/MAX($AK4:$AV4)*100 -> 77.877047 | AC4: =AO4/MAX($AK4:$AV4)*100 -> 0 | AD4: =AP4/MAX($AK4:$AV4)*100 -> 0 | AE4: =AQ4/MAX($AK4:$AV4)*100 -> 97.195587 | AF4: =AR4/MAX($AK4:$AV4)*100 -> 96.785805 | ... AJ4: =AV4/MAX($AK4:$AV4)*100 -> 0 | AK4: {=_xlfn.IFS(AZ4=0,0,AZ4>0,(LOG(0.01*AZ4/10^-CD4)))} -> 6.5774968 | AL4: {=_xlfn.IFS(BA4=0,0,BA4>0,(LOG(0.01*BA4/10^-CE4)))} -> 5.8987872 | AM4: {=_xlfn.IFS(BB4=0,0,BB4>0,(LOG(0.01*BB4/10^-CF4)))} -> 0 | AN4: {=_xlfn.IFS(BC4=0,0,BC4>0,(LOG(0.01*BC4/10^-CG4)))} -> 6.0517233 | AO4: {=_xlfn.IFS(BD4=0,0,BD4>0,(LOG(0.01*BD4/10^-CH4)))} -> 0 | AP4: {=_xlfn.IFS(BE4=0,0,BE4>0,(LOG(0.01*BE4/10^-CI4)))} -> 0 | AQ4: {=_xlfn.IFS(BF4=0,0,BF4>0,(LOG(0.01*BF4/10^-CJ4)))} -> 7.5529417 | AR4: {=_xlfn.IFS(BG4=0,0,BG4>0,(LOG(0.01*BG4/10^-CK4)))} -> 7.521098 | ... AY4: {=_xlfn.IFS(BN4=0,0,BN4>0,(LOG(0.01*BN4/10^-CR4)))} -> 4.8046831 | AZ4: =IF(BO4="",0,100*BO4/MAX(BO:BO)) -> 56.950398 | BA4: =IF(BP4="",0,100*BP4/MAX($BP:$BT)) -> 4.5059588 | BB4: =IF(BQ4="",0,100*BQ4/MAX($BP:$BT)) -> 0 | BC4: =IF(BR4="",0,100*BR4/MAX($BP:$BT)) -> 4.127844 | BD4: =IF(BS4="",0,100*BS4/MAX($BP:$BT)) -> 0 | BE4: =IF(BT4="",0,100*BT4/MAX($BP:$BT)) -> 0 | BF4: =IF(BU4="",0,100*BU4/MAX($BU:$BX)) -> 64.854733 | BG4: =IF(BV4="",0,100*BV4/MAX($BU:$BX)) -> 70 | BH4: =IF(BW4="",0,100*BW4/MAX($BU:$BX)) -> 77.553889 | BI4: =IF(BX4="",0,100*BX4/MAX($BU:$BX)) -> 97.469541 | BJ4: =IF(BY4="",0,100*BY4/MAX($BY:$BZ)) -> 0 | BK4: =IF(BZ4="",0,100*BZ4/MAX($BY:$BZ)) -> 0 | BL4: =IF(CA4="",0,100*CA4/MAX($CA:$CC)) -> 0 | BM4: =IF(CB4="",0,100*CB4/MAX($CA:$CC)) -> 0 | BN4: =IF(CC4="",0,100*CC4/MAX($CA:$CC)) -> 0.63779792 | BO4: 37.2 | BP4: 41.59 | BR4: 38.1 | BU4: 692 | BV4: 746.9 | BW4: 827.5 | BX4: 1040 | CC4: 19 | CD4: 6.822 | CE4: 7.245 | CG4: 7.436 | CJ4: 7.741 | CK4: 7.676 | CL4: 6.713 | CM4: 7.782 | CR4: 7 | CS4: =IF(VLOOKUP($A4,'B-Ligands'!$A:$G,3,FALSE)="","",VLOOKUP($A4,'B-Ligands'!$A:$G,3,FALSE)) | CT4: =IF(VLOOKUP($A4,'B-Ligands'!$A:$G,4,FALSE)="","",VLOOKUP($A4,'B-Ligands'!$A:$G,4,FALSE)) -> Noradrenaline | CU4: 13.356204 | CV4: 26.030223 | CW4: 22.377925 | CX4: 20.76389 | CY4: 5.8149319 | CZ4: 43.144067 | DA4: 24.579985 | DB4: 24.593236 | DC4: 27.979712 | DD4: 12.609481 | DE4: 23.13181 | DF4: 29.783522 | DG4: 47.249447 | DH4: 50.450375 | DI4: 15.540808 | DJ4: =IF(BO4="",0,BO4/CU4) -> 2.7852225 | DK4: =IF(BP4="",0,BP4/CV4) -> 1.5977581 | DL4: =IF(BQ4="",0,BQ4/CW4) -> 0 | DM4: =IF(BR4="",0,BR4/CX4) -> 1.8349163 | DN4: =IF(BS4="",0,BS4/CY4) -> 0 | DO4: =IF(BT4="",0,BT4/CZ4) -> 0 | DP4: =IF(BU4="",0,BU4/DA4) -> 28.152987 | DQ4: =IF(BV4="",0,BV4/DB4) -> 30.370139 | ... DX4: =IF(CC4="",0,CC4/DI4) -> 1.2225876
A5: ACM2 | B5: 10.7554/eLife.74101 | C5: =IF(VLOOKUP($A5,'B-Ligands'!$A:$G,5,FALSE)="","",VLOOKUP($A5,'B-Ligands'!$A:$G,5,FALSE)) -> Guide To Pharmacology | D5: =IF(VLOOKUP($A5,'B-Ligands'!$A:$G,6,FALSE)="","",VLOOKUP($A5,'B-Ligands'!$A:$G,6,FALSE)) -> 294 | E5: =IF(VLOOKUP($A5,'B-Ligands'!$A:$G,7,FALSE)="","",VLOOKUP($A5,'B-Ligands'!$A:$G,7,FALSE)) -> Phys | F5: =IF(T5>0,1,"") -> 1 | G5: =IF(U5>0,1,"") -> 1 | H5: =IF(V5>0,1,"") -> 1 | I5: =IF(W5>0,1,"") | J5: =COUNTIF(L5:O5,">0") -> 3 | K5: =SUBSTITUTE(INDEX(T$1:W$1,1,MATCH(MAX(T5:W5),T5:W5,0)),"-fam","") -> Gi/o | L5: =IF(T5=0,0,_xlfn.RANK.EQ(T5,$T5:$W5,0)) -> 3 | M5: =IF(U5=0,0,_xlfn.RANK.EQ(U5,$T5:$W5,0)) -> 1 | N5: =IF(V5=0,0,_xlfn.RANK.EQ(V5,$T5:$W5,0)) -> 2 | O5: =IF(W5=0,0,_xlfn.RANK.EQ(W5,$T5:$W5,0)) -> 0 | P5: =T5/MAX($T5:$W5)*100 -> 65.080576 | Q5: =U5/MAX($T5:$W5)*100 -> 100 | R5: =V5/MAX($T5:$W5)*100 -> 86.322501 | S5: =W5/MAX($T5:$W5)*100 -> 0 | T5: =AK5 -> 5.6068425 | U5: =MAX(AL5:AP5) -> 8.6152319 | V5: =MAX(AQ5:AT5) -> 7.4368836 | W5: =MAX(AU5:AV5) -> 0 | X5: =INDEX(AK$1:AV$1,1,MATCH(MAX(AK5:AV5),AK5:AV5,0)) -> GoB | Y5: =AK5/MAX($AK5:$AV5)*100 -> 65.080576 | Z5: =AL5/MAX($AK5:$AV5)*100 -> 92.032275 | AA5: =AM5/MAX($AK5:$AV5)*100 -> 87.882813 | AB5: =AN5/MAX($AK5:$AV5)*100 -> 93.510985 | AC5: =AO5/MAX($AK5:$AV5)*100 -> 100 | AD5: =AP5/MAX($AK5:$AV5)*100 -> 92.488583 | AE5: =AQ5/MAX($AK5:$AV5)*100 -> 0 | AF5: =AR5/MAX($AK5:$AV5)*100 -> 0 | ... AJ5: =AV5/MAX($AK5:$AV5)*100 -> 0 | AK5: {=_xlfn.IFS(AZ5=0,0,AZ5>0,(LOG(0.01*AZ5/10^-CD5)))} -> 5.6068425 | AL5: {=_xlfn.IFS(BA5=0,0,BA5>0,(LOG(0.01*BA5/10^-CE5)))} -> 7.9287939 | AM5: {=_xlfn.IFS(BB5=0,0,BB5>0,(LOG(0.01*BB5/10^-CF5)))} -> 7.5713081 | AN5: {=_xlfn.IFS(BC5=0,0,BC5>0,(LOG(0.01*BC5/10^-CG5)))} -> 8.0561881 | AO5: {=_xlfn.IFS(BD5=0,0,BD5>0,(LOG(0.01*BD5/10^-CH5)))} -> 8.6152319 | AP5: {=_xlfn.IFS(BE5=0,0,BE5>0,(LOG(0.01*BE5/10^-CI5)))} -> 7.9681059 | AQ5: {=_xlfn.IFS(BF5=0,0,BF5>0,(LOG(0.01*BF5/10^-CJ5)))} -> 0 | AR5: {=_xlfn.IFS(BG5=0,0,BG5>0,(LOG(0.01*BG5/10^-CK5)))} -> 0 | ... AY5: {=_xlfn.IFS(BN5=0,0,BN5>0,(LOG(0.01*BN5/10^-CR5)))} -> 7.2072554 | AZ5: =IF(BO5="",0,100*BO5/MAX(BO:BO)) -> 34.185548 | BA5: =IF(BP5="",0,100*BP5/MAX($BP:$BT)) -> 72.242687 | BB5: =IF(BQ5="",0,100*BQ5/MAX($BP:$BT)) -> 42.296858 | BC5: =IF(BR5="",0,100*BR5/MAX($BP:$BT)) -> 26.435536 | BD5: =IF(BS5="",0,100*BS5/MAX($BP:$BT)) -> 36.327194 | BE5: =IF(BT5="",0,100*BT5/MAX($BP:$BT)) -> 28.255688 | BF5: =IF(BU5="",0,100*BU5/MAX($BU:$BX)) -> 0 | BG5: =IF(BV5="",0,100*BV5/MAX($BU:$BX)) -> 0 | BH5: =IF(BW5="",0,100*BW5/MAX($BU:$BX)) -> 11.246485 | BI5: =IF(BX5="",0,100*BX5/MAX($BU:$BX)) -> 89.718838 | BJ5: =IF(BY5="",0,100*BY5/MAX($BY:$BZ)) -> 0 | BK5: =IF(BZ5="",0,100*BZ5/MAX($BY:$BZ)) -> 0 | BL5: =IF(CA5="",0,100*CA5/MAX($CA:$CC)) -> 48.3048 | BM5: =IF(CB5="",0,100*CB5/MAX($CA:$CC)) -> 27.593152 | BN5: =IF(CC5="",0,100*CC5/MAX($CA:$CC)) -> 39.107083 | BO5: 22.33 | BP5: 666.8 | BQ5: 390.4 | BR5: 244 | BS5: 335.3 | BT5: 260.8 | BW5: 120 | BX5: 957.3 | CA5: 1439 | CB5: 822 | CC5: 1165 | CD5: 6.073 | CE5: 8.07 | CF5: 7.945 | CG5: 8.634 | CH5: 9.055 | CI5: 8.517 | CL5: 5.442 | CM5: 7.484 | CP5: 7.34 | CQ5: 5.838 | CR5: 7.615 | CS5: =IF(VLOOKUP($A5,'B-Ligands'!$A:$G,3,FALSE)="","",VLOOKUP($A5,'B-Ligands'!$A:$G,3,FALSE)) | CT5: =IF(VLOOKUP($A5,'B-Ligands'!$A:$G,4,FALSE)="","",VLOOKUP($A5,'B-Ligands'!$A:$G,4,FALSE)) -> Acetylcholine | CU5: 7.7106114 | CV5: 6.4708387 | CW5: 6.048432 | CX5: 8.6429457 | CY5: 5.2789549 | CZ5: 12.340907 | DA5: 6.2282612 | DB5: 5.9777928 | DC5: 0.98994322 | DD5: 6.2440639 | DE5: 4.2230857 | DF5: 15.182255 | DG5: 9.4496451 | DH5: 7.1145558 | DI5: 11.288351 | DJ5: =IF(BO5="",0,BO5/CU5) -> 2.896009 | DK5: =IF(BP5="",0,BP5/CV5) -> 103.04692 | DL5: =IF(BQ5="",0,BQ5/CW5) -> 64.545654 | DM5: =IF(BR5="",0,BR5/CX5) -> 28.231116 | DN5: =IF(BS5="",0,BS5/CY5) -> 63.51636 | DO5: =IF(BT5="",0,BT5/CZ5) -> 21.132969 | DP5: =IF(BU5="",0,BU5/DA5) -> 0 | DQ5: =IF(BV5="",0,BV5/DB5) -> 0 | ... DX5: =IF(CC5="",0,CC5/DI5) -> 103.20374
A6: ACM1 | B6: 10.7554/eLife.74101 | C6: =IF(VLOOKUP($A6,'B-Ligands'!$A:$G,5,FALSE)="","",VLOOKUP($A6,'B-Ligands'!$A:$G,5,FALSE)) -> Guide To Pharmacology | D6: =IF(VLOOKUP($A6,'B-Ligands'!$A:$G,6,FALSE)="","",VLOOKUP($A6,'B-Ligands'!$A:$G,6,FALSE)) -> 294 | E6: =IF(VLOOKUP($A6,'B-Ligands'!$A:$G,7,FALSE)="","",VLOOKUP($A6,'B-Ligands'!$A:$G,7,FALSE)) -> Phys | F6: =IF(T6>0,1,"") -> 1 | G6: =IF(U6>0,1,"") -> 1 | H6: =IF(V6>0,1,"") -> 1 | I6: =IF(W6>0,1,"") | J6: =COUNTIF(L6:O6,">0") -> 3 | K6: =SUBSTITUTE(INDEX(T$1:W$1,1,MATCH(MAX(T6:W6),T6:W6,0)),"-fam","") -> Gq/11 | L6: =IF(T6=0,0,_xlfn.RANK.EQ(T6,$T6:$W6,0)) -> 2 | M6: =IF(U6=0,0,_xlfn.RANK.EQ(U6,$T6:$W6,0)) -> 3 | N6: =IF(V6=0,0,_xlfn.RANK.EQ(V6,$T6:$W6,0)) -> 1 | O6: =IF(W6=0,0,_xlfn.RANK.EQ(W6,$T6:$W6,0)) -> 0 | P6: =T6/MAX($T6:$W6)*100 -> 75.14284 | Q6: =U6/MAX($T6:$W6)*100 -> 67.872973 | R6: =V6/MAX($T6:$W6)*100 -> 100 | S6: =W6/MAX($T6:$W6)*100 -> 0 | T6: =AK6 -> 5.8309946 | U6: =MAX(AL6:AP6) -> 5.2668616 | V6: =MAX(AQ6:AT6) -> 7.7598805 | W6: =MAX(AU6:AV6) -> 0 | X6: =INDEX(AK$1:AV$1,1,MATCH(MAX(AK6:AV6),AK6:AV6,0)) -> G11 | Y6: =AK6/MAX($AK6:$AV6)*100 -> 75.14284 | Z6: =AL6/MAX($AK6:$AV6)*100 -> 63.523304 | AA6: =AM6/MAX($AK6:$AV6)*100 -> 59.059812 | AB6: =AN6/MAX($AK6:$AV6)*100 -> 56.637427 | AC6: =AO6/MAX($AK6:$AV6)*100 -> 61.49901 | AD6: =AP6/MAX($AK6:$AV6)*100 -> 67.872973 | AE6: =AQ6/MAX($AK6:$AV6)*100 -> 97.012772 | AF6: =AR6/MAX($AK6:$AV6)*100 -> 100 | ... AJ6: =AV6/MAX($AK6:$AV6)*100 -> 0 | AK6: {=_xlfn.IFS(AZ6=0,0,AZ6>0,(LOG(0.01*AZ6/10^-CD6)))} -> 5.8309946 | AL6: {=_xlfn.IFS(BA6=0,0,BA6>0,(LOG(0.01*BA6/10^-CE6)))} -> 4.9293325 | AM6: {=_xlfn.IFS(BB6=0,0,BB6>0,(LOG(0.01*BB6/10^-CF6)))} -> 4.5829708 | AN6: {=_xlfn.IFS(BC6=0,0,BC6>0,(LOG(0.01*BC6/10^-CG6)))} -> 4.3949967 | AO6: {=_xlfn.IFS(BD6=0,0,BD6>0,(LOG(0.01*BD6/10^-CH6)))} -> 4.7722497 | AP6: {=_xlfn.IFS(BE6=0,0,BE6>0,(LOG(0.01*BE6/10^-CI6)))} -> 5.2668616 | AQ6: {=_xlfn.IFS(BF6=0,0,BF6>0,(LOG(0.01*BF6/10^-CJ6)))} -> 7.5280752 | AR6: {=_xlfn.IFS(BG6=0,0,BG6>0,(LOG(0.01*BG6/10^-CK6)))} -> 7.7598805 | ... AY6: {=_xlfn.IFS(BN6=0,0,BN6>0,(LOG(0.01*BN6/10^-CR6)))} -> 3.9485597 | AZ6: =IF(BO6="",0,100*BO6/MAX(BO:BO)) -> 52.480098 | BA6: =IF(BP6="",0,100*BP6/MAX($BP:$BT)) -> 28.862405 | BB6: =IF(BQ6="",0,100*BQ6/MAX($BP:$BT)) -> 17.497291 | BC6: =IF(BR6="",0,100*BR6/MAX($BP:$BT)) -> 13.304442 | BD6: =IF(BS6="",0,100*BS6/MAX($BP:$BT)) -> 23.672806 | BE6: =IF(BT6="",0,100*BT6/MAX($BP:$BT)) -> 22.535211 | BF6: =IF(BU6="",0,100*BU6/MAX($BU:$BX)) -> 50.824742 | BG6: =IF(BV6="",0,100*BV6/MAX($BU:$BX)) -> 57.132146 | BH6: =IF(BW6="",0,100*BW6/MAX($BU:$BX)) -> 71.565136 | BI6: =IF(BX6="",0,100*BX6/MAX($BU:$BX)) -> 83.514527 | BJ6: =IF(BY6="",0,100*BY6/MAX($BY:$BZ)) -> 0 | BK6: =IF(BZ6="",0,100*BZ6/MAX($BY:$BZ)) -> 0 | BL6: =IF(CA6="",0,100*CA6/MAX($CA:$CC)) -> 0 | BM6: =IF(CB6="",0,100*CB6/MAX($CA:$CC)) -> 3.4676066 | BN6: =IF(CC6="",0,100*CC6/MAX($CA:$CC)) -> 6.8479355 | BO6: 34.28 | BP6: 266.4 | BQ6: 161.5 | BR6: 122.8 | BS6: 218.5 | BT6: 208 | BU6: 542.3 | BV6: 609.6 | BW6: 763.6 | BX6: 891.1 | CB6: 103.3 | CC6: 204 | CD6: 6.111 | CE6: 5.469 | CF6: 5.34 | CG6: 5.271 | CH6: 5.398 | CI6: 5.914 | CJ6: 7.822 | CK6: 8.003 | CL6: 7.771 | CM6: 7.722 | CQ6: 5.167 | CR6: 5.113 | CS6: =IF(VLOOKUP($A6,'B-Ligands'!$A:$G,3,FALSE)="","",VLOOKUP($A6,'B-Ligands'!$A:$G,3,FALSE)) | CT6: =IF(VLOOKUP($A6,'B-Ligands'!$A:$G,4,FALSE)="","",VLOOKUP($A6,'B-Ligands'!$A:$G,4,FALSE)) -> Acetylcholine | CU6: 6.7165547 | CV6: 23.939753 | CW6: 11.225934 | CX6: 22.316417 | CY6: 22.174459 | CZ6: 14.22569 | DA6: 15.575205 | DB6: 9.545719 | DC6: 6.1994609 | DD6: 12.330702 | DE6: 2.8282415 | DF6: 8.1478211 | DG6: 11.279803 | DH6: 3.8602427 | DI6: 11.226908 | DJ6: =IF(BO6="",0,BO6/CU6) -> 5.1038071 | DK6: =IF(BP6="",0,BP6/CV6) -> 11.127935 | DL6: =IF(BQ6="",0,BQ6/CW6) -> 14.386331 | DM6: =IF(BR6="",0,BR6/CX6) -> 5.5026755 | DN6: =IF(BS6="",0,BS6/CY6) -> 9.853679 | DO6: =IF(BT6="",0,BT6/CZ6) -> 14.621435 | DP6: =IF(BU6="",0,BU6/DA6) -> 34.818161 | DQ6: =IF(BV6="",0,BV6/DB6) -> 63.861088 | ... DX6: =IF(CC6="",0,CC6/DI6) -> 18.17063
A7: ADA2A | B7: 10.7554/eLife.74101 | C7: =IF(VLOOKUP($A7,'B-Ligands'!$A:$G,5,FALSE)="","",VLOOKUP($A7,'B-Ligands'!$A:$G,5,FALSE)) -> Guide To Pharmacology | D7: =IF(VLOOKUP($A7,'B-Ligands'!$A:$G,6,FALSE)="","",VLOOKUP($A7,'B-Ligands'!$A:$G,6,FALSE)) -> 484 | E7: =IF(VLOOKUP($A7,'B-Ligands'!$A:$G,7,FALSE)="","",VLOOKUP($A7,'B-Ligands'!$A:$G,7,FALSE)) -> Phys | F7: =IF(T7>0,1,"") -> 1 | G7: =IF(U7>0,1,"") -> 1 | H7: =IF(V7>0,1,"") -> 1 | I7: =IF(W7>0,1,"") -> 1 | J7: =COUNTIF(L7:O7,">0") -> 4 | K7: =SUBSTITUTE(INDEX(T$1:W$1,1,MATCH(MAX(T7:W7),T7:W7,0)),"-fam","") -> Gi/o | L7: =IF(T7=0,0,_xlfn.RANK.EQ(T7,$T7:$W7,0)) -> 4 | M7: =IF(U7=0,0,_xlfn.RANK.EQ(U7,$T7:$W7,0)) -> 1 | N7: =IF(V7=0,0,_xlfn.RANK.EQ(V7,$T7:$W7,0)) -> 2 | O7: =IF(W7=0,0,_xlfn.RANK.EQ(W7,$T7:$W7,0)) -> 3 | P7: =T7/MAX($T7:$W7)*100 -> 58.189345 | Q7: =U7/MAX($T7:$W7)*100 -> 100 | R7: =V7/MAX($T7:$W7)*100 -> 68.3815 | S7: =W7/MAX($T7:$W7)*100 -> 59.92867 | T7: =AK7 -> 5.3027086 | U7: =MAX(AL7:AP7) -> 9.1128515 | V7: =MAX(AQ7:AT7) -> 6.2315046 | W7: =MAX(AU7:AV7) -> 5.4612107 | X7: =INDEX(AK$1:AV$1,1,MATCH(MAX(AK7:AV7),AK7:AV7,0)) -> Gz | Y7: =AK7/MAX($AK7:$AV7)*100 -> 58.189345 | Z7: =AL7/MAX($AK7:$AV7)*100 -> 93.131138 | AA7: =AM7/MAX($AK7:$AV7)*100 -> 91.020071 | AB7: =AN7/MAX($AK7:$AV7)*100 -> 90.753073 | AC7: =AO7/MAX($AK7:$AV7)*100 -> 96.239792 | AD7: =AP7/MAX($AK7:$AV7)*100 -> 100 | AE7: =AQ7/MAX($AK7:$AV7)*100 -> 50.138397 | AF7: =AR7/MAX($AK7:$AV7)*100 -> 48.571168 | ... AJ7: =AV7/MAX($AK7:$AV7)*100 -> 59.92867 | AK7: {=_xlfn.IFS(AZ7=0,0,AZ7>0,(LOG(0.01*AZ7/10^-CD7)))} -> 5.3027086 | AL7: {=_xlfn.IFS(BA7=0,0,BA7>0,(LOG(0.01*BA7/10^-CE7)))} -> 8.4869023 | AM7: {=_xlfn.IFS(BB7=0,0,BB7>0,(LOG(0.01*BB7/10^-CF7)))} -> 8.2945239 | AN7: {=_xlfn.IFS(BC7=0,0,BC7>0,(LOG(0.01*BC7/10^-CG7)))} -> 8.2701927 | AO7: {=_xlfn.IFS(BD7=0,0,BD7>0,(LOG(0.01*BD7/10^-CH7)))} -> 8.7701893 | AP7: {=_xlfn.IFS(BE7=0,0,BE7>0,(LOG(0.01*BE7/10^-CI7)))} -> 9.1128515 | AQ7: {=_xlfn.IFS(BF7=0,0,BF7>0,(LOG(0.01*BF7/10^-CJ7)))} -> 4.5690377 | AR7: {=_xlfn.IFS(BG7=0,0,BG7>0,(LOG(0.01*BG7/10^-CK7)))} -> 4.4262184 | ... AY7: {=_xlfn.IFS(BN7=0,0,BN7>0,(LOG(0.01*BN7/10^-CR7)))} -> 5.6965993 | AZ7: =IF(BO7="",0,100*BO7/MAX(BO:BO)) -> 27.587263 | BA7: =IF(BP7="",0,100*BP7/MAX($BP:$BT)) -> 93.304442 | BB7: =IF(BQ7="",0,100*BQ7/MAX($BP:$BT)) -> 52.665222 | BC7: =IF(BR7="",0,100*BR7/MAX($BP:$BT)) -> 25.774648 | BD7: =IF(BS7="",0,100*BS7/MAX($BP:$BT)) -> 42.091008 | BE7: =IF(BT7="",0,100*BT7/MAX($BP:$BT)) -> 12.101842 | BF7: =IF(BU7="",0,100*BU7/MAX($BU:$BX)) -> 5.284911 | BG7: =IF(BV7="",0,100*BV7/MAX($BU:$BX)) -> 2.7366448 | BH7: =IF(BW7="",0,100*BW7/MAX($BU:$BX)) -> 6.1443299 | BI7: =IF(BX7="",0,100*BX7/MAX($BU:$BX)) -> 81.565136 | BJ7: =IF(BY7="",0,100*BY7/MAX($BY:$BZ)) -> 9.5865194 | BK7: =IF(BZ7="",0,100*BZ7/MAX($BY:$BZ)) -> 64.004531 | BL7: =IF(CA7="",0,100*CA7/MAX($CA:$CC)) -> 22.121517 | BM7: =IF(CB7="",0,100*CB7/MAX($CA:$CC)) -> 12.272575 | BN7: =IF(CC7="",0,100*CC7/MAX($CA:$CC)) -> 22.366566 | BO7: 18.02 | BP7: 861.2 | BQ7: 486.1 | BR7: 237.9 | BS7: 388.5 | BT7: 111.7 | BU7: 56.39 | BV7: 29.2 | BW7: 65.56 | BX7: 870.3 | BY7: 67.7 | BZ7: 452 | CA7: 659 | CB7: 365.6 | CC7: 666.3 | CD7: 5.862 | CE7: 8.517 | CF7: 8.573 | CG7: 8.859 | CH7: 9.146 | CI7: 10.03 | CJ7: 5.846 | CK7: 5.989 | CL7: 5.649 | CM7: 6.32 | CN7: 6.194 | CO7: 5.655 | CP7: 6.226 | CQ7: 6.008 | CR7: 6.347 | CS7: =IF(VLOOKUP($A7,'B-Ligands'!$A:$G,3,FALSE)="","",VLOOKUP($A7,'B-Ligands'!$A:$G,3,FALSE)) | CT7: =IF(VLOOKUP($A7,'B-Ligands'!$A:$G,4,FALSE)="","",VLOOKUP($A7,'B-Ligands'!$A:$G,4,FALSE)) -> Noradrenaline | CU7: 5.8215552 | CV7: 37.099262 | CW7: 59.735646 | CX7: 51.44338 | CY7: 50.365175 | CZ7: 3.7113204 | DA7: 21.956162 | DB7: 6.3515304 | DC7: 23.784252 | DD7: 20.014695 | DE7: 11.481139 | DF7: 2.9700792 | DG7: 29.800985 | DH7: 20.369691 | DI7: 27.07782 | DJ7: =IF(BO7="",0,BO7/CU7) -> 3.0953928 | DK7: =IF(BP7="",0,BP7/CV7) -> 23.2134 | DL7: =IF(BQ7="",0,BQ7/CW7) -> 8.1375198 | DM7: =IF(BR7="",0,BR7/CX7) -> 4.6245018 | DN7: =IF(BS7="",0,BS7/CY7) -> 7.7136633 | DO7: =IF(BT7="",0,BT7/CZ7) -> 30.097105 | DP7: =IF(BU7="",0,BU7/DA7) -> 2.5682995 | DQ7: =IF(BV7="",0,BV7/DB7) -> 4.5973172 | ... DX7: =IF(CC7="",0,CC7/DI7) -> 24.606855
A8: ACM4 | B8: 10.7554/eLife.74101 | C8: =IF(VLOOKUP($A8,'B-Ligands'!$A:$G,5,FALSE)="","",VLOOKUP($A8,'B-Ligands'!$A:$G,5,FALSE)) -> Guide To Pharmacology | D8: =IF(VLOOKUP($A8,'B-Ligands'!$A:$G,6,FALSE)="","",VLOOKUP($A8,'B-Ligands'!$A:$G,6,FALSE)) -> 294 | E8: =IF(VLOOKUP($A8,'B-Ligands'!$A:$G,7,FALSE)="","",VLOOKUP($A8,'B-Ligands'!$A:$G,7,FALSE)) -> Phys | F8: =IF(T8>0,1,"") | G8: =IF(U8>0,1,"") -> 1 | H8: =IF(V8>0,1,"") -> 1 | I8: =IF(W8>0,1,"") | J8: =COUNTIF(L8:O8,">0") -> 2 | K8: =SUBSTITUTE(INDEX(T$1:W$1,1,MATCH(MAX(T8:W8),T8:W8,0)),"-fam","") -> Gi/o | L8: =IF(T8=0,0,_xlfn.RANK.EQ(T8,$T8:$W8,0)) -> 0 | M8: =IF(U8=0,0,_xlfn.RANK.EQ(U8,$T8:$W8,0)) -> 1 | N8: =IF(V8=0,0,_xlfn.RANK.EQ(V8,$T8:$W8,0)) -> 2 | O8: =IF(W8=0,0,_xlfn.RANK.EQ(W8,$T8:$W8,0)) -> 0 | P8: =T8/MAX($T8:$W8)*100 -> 0 | Q8: =U8/MAX($T8:$W8)*100 -> 100 | R8: =V8/MAX($T8:$W8)*100 -> 78.439878 | S8: =W8/MAX($T8:$W8)*100 -> 0 | T8: =AK8 -> 0 | U8: =MAX(AL8:AP8) -> 8.7404589 | V8: =MAX(AQ8:AT8) -> 6.8560053 | W8: =MAX(AU8:AV8) -> 0 | X8: =INDEX(AK$1:AV$1,1,MATCH(MAX(AK8:AV8),AK8:AV8,0)) -> GoB | Y8: =AK8/MAX($AK8:$AV8)*100 -> 0 | Z8: =AL8/MAX($AK8:$AV8)*100 -> 92.840134 | AA8: =AM8/MAX($AK8:$AV8)*100 -> 94.034547 | AB8: =AN8/MAX($AK8:$AV8)*100 -> 91.982018 | AC8: =AO8/MAX($AK8:$AV8)*100 -> 100 | AD8: =AP8/MAX($AK8:$AV8)*100 -> 90.293395 | AE8: =AQ8/MAX($AK8:$AV8)*100 -> 52.153615 | AF8: =AR8/MAX($AK8:$AV8)*100 -> 0 | ... AJ8: =AV8/MAX($AK8:$AV8)*100 -> 0 | AK8: {=_xlfn.IFS(AZ8=0,0,AZ8>0,(LOG(0.01*AZ8/10^-CD8)))} -> 0 | AL8: {=_xlfn.IFS(BA8=0,0,BA8>0,(LOG(0.01*BA8/10^-CE8)))} -> 8.1146537 | AM8: {=_xlfn.IFS(BB8=0,0,BB8>0,(LOG(0.01*BB8/10^-CF8)))} -> 8.2190509 | AN8: {=_xlfn.IFS(BC8=0,0,BC8>0,(LOG(0.01*BC8/10^-CG8)))} -> 8.0396505 | AO8: {=_xlfn.IFS(BD8=0,0,BD8>0,(LOG(0.01*BD8/10^-CH8)))} -> 8.7404589 | AP8: {=_xlfn.IFS(BE8=0,0,BE8>0,(LOG(0.01*BE8/10^-CI8)))} -> 7.8920571 | AQ8: {=_xlfn.IFS(BF8=0,0,BF8>0,(LOG(0.01*BF8/10^-CJ8)))} -> 4.5584653 | AR8: {=_xlfn.IFS(BG8=0,0,BG8>0,(LOG(0.01*BG8/10^-CK8)))} -> 0 | ... AY8: {=_xlfn.IFS(BN8=0,0,BN8>0,(LOG(0.01*BN8/10^-CR8)))} -> 6.3744095 | AZ8: =IF(BO8="",0,100*BO8/MAX(BO:BO)) -> 0 | BA8: =IF(BP8="",0,100*BP8/MAX($BP:$BT)) -> 75.622969 | BB8: =IF(BQ8="",0,100*BQ8/MAX($BP:$BT)) -> 65.471289 | BC8: =IF(BR8="",0,100*BR8/MAX($BP:$BT)) -> 29.967497 | BD8: =IF(BS8="",0,100*BS8/MAX($BP:$BT)) -> 37.107259 | BE8: =IF(BT8="",0,100*BT8/MAX($BP:$BT)) -> 16.59805 | BF8: =IF(BU8="",0,100*BU8/MAX($BU:$BX)) -> 6.8622306 | BG8: =IF(BV8="",0,100*BV8/MAX($BU:$BX)) -> 0 | BH8: =IF(BW8="",0,100*BW8/MAX($BU:$BX)) -> 13.552015 | BI8: =IF(BX8="",0,100*BX8/MAX($BU:$BX)) -> 81.471415 | BJ8: =IF(BY8="",0,100*BY8/MAX($BY:$BZ)) -> 0 | BK8: =IF(BZ8="",0,100*BZ8/MAX($BY:$BZ)) -> 0 | BL8: =IF(CA8="",0,100*CA8/MAX($CA:$CC)) -> 22.265861 | BM8: =IF(CB8="",0,100*CB8/MAX($CA:$CC)) -> 7.5293723 | BN8: =IF(CC8="",0,100*CC8/MAX($CA:$CC)) -> 23.900638 | BP8: 698 | BQ8: 604.3 | BR8: 276.6 | BS8: 342.5 | BT8: 153.2 | BU8: 73.22 | BW8: 144.6 | BX8: 869.3 | CA8: 663.3 | CB8: 224.3 | CC8: 712 | CE8: 8.236 | CF8: 8.403 | CG8: 8.563 | CH8: 9.171 | CI8: 8.672 | CJ8: 5.722 | CL8: 5.733 | CM8: 6.945 | CP8: 6.543 | CQ8: 6.052 | CR8: 6.996 | CS8: =IF(VLOOKUP($A8,'B-Ligands'!$A:$G,3,FALSE)="","",VLOOKUP($A8,'B-Ligands'!$A:$G,3,FALSE)) | CT8: =IF(VLOOKUP($A8,'B-Ligands'!$A:$G,4,FALSE)="","",VLOOKUP($A8,'B-Ligands'!$A:$G,4,FALSE)) -> Acetylcholine | CU8: 17.264792 | CV8: 14.56499 | CW8: 8.848352 | CX8: 20.1353 | CY8: 17.59767 | CZ8: 17.030247 | DA8: 7.8726425 | DB8: 26.242508 | DC8: 8.3534807 | DD8: 10.570513 | DE8: 9.930764 | DF8: 10.971177 | DG8: 29.972769 | DH8: 8.4031974 | DI8: 3.6730104 | DJ8: =IF(BO8="",0,BO8/CU8) -> 0 | DK8: =IF(BP8="",0,BP8/CV8) -> 47.923136 | DL8: =IF(BQ8="",0,BQ8/CW8) -> 68.295203 | DM8: =IF(BR8="",0,BR8/CX8) -> 13.737069 | DN8: =IF(BS8="",0,BS8/CY8) -> 19.462804 | DO8: =IF(BT8="",0,BT8/CZ8) -> 8.9957591 | DP8: =IF(BU8="",0,BU8/DA8) -> 9.3005621 | DQ8: =IF(BV8="",0,BV8/DB8) -> 0 | ... DX8: =IF(CC8="",0,CC8/DI8) -> 193.84644
A9: V1AR | B9: 10.7554/eLife.74101 | C9: =IF(VLOOKUP($A9,'B-Ligands'!$A:$G,5,FALSE)="","",VLOOKUP($A9,'B-Ligands'!$A:$G,5,FALSE)) -> Guide To Pharmacology | D9: =IF(VLOOKUP($A9,'B-Ligands'!$A:$G,6,FALSE)="","",VLOOKUP($A9,'B-Ligands'!$A:$G,6,FALSE)) -> 2168 | E9: =IF(VLOOKUP($A9,'B-Ligands'!$A:$G,7,FALSE)="","",VLOOKUP($A9,'B-Ligands'!$A:$G,7,FALSE)) -> Phys | F9: =IF(T9>0,1,"") | G9: =IF(U9>0,1,"") -> 1 | H9: =IF(V9>0,1,"") -> 1 | I9: =IF(W9>0,1,"") | J9: =COUNTIF(L9:O9,">0") -> 2 | K9: =SUBSTITUTE(INDEX(T$1:W$1,1,MATCH(MAX(T9:W9),T9:W9,0)),"-fam","") -> Gq/11 | L9: =IF(T9=0,0,_xlfn.RANK.EQ(T9,$T9:$W9,0)) -> 0 | M9: =IF(U9=0,0,_xlfn.RANK.EQ(U9,$T9:$W9,0)) -> 2 | N9: =IF(V9=0,0,_xlfn.RANK.EQ(V9,$T9:$W9,0)) -> 1 | O9: =IF(W9=0,0,_xlfn.RANK.EQ(W9,$T9:$W9,0)) -> 0 | P9: =T9/MAX($T9:$W9)*100 -> 0 | Q9: =U9/MAX($T9:$W9)*100 -> 80.355086 | R9: =V9/MAX($T9:$W9)*100 -> 100 | S9: =W9/MAX($T9:$W9)*100 -> 0 | T9: =AK9 -> 0 | U9: =MAX(AL9:AP9) -> 6.9991878 | V9: =MAX(AQ9:AT9) -> 8.7103233 | W9: =MAX(AU9:AV9) -> 0 | X9: =INDEX(AK$1:AV$1,1,MATCH(MAX(AK9:AV9),AK9:AV9,0)) -> G11 | Y9: =AK9/MAX($AK9:$AV9)*100 -> 0 | Z9: =AL9/MAX($AK9:$AV9)*100 -> 78.418355 | AA9: =AM9/MAX($AK9:$AV9)*100 -> 77.002524 | AB9: =AN9/MAX($AK9:$AV9)*100 -> 79.471288 | AC9: =AO9/MAX($AK9:$AV9)*100 -> 78.153941 | AD9: =AP9/MAX($AK9:$AV9)*100 -> 80.355086 | AE9: =AQ9/MAX($AK9:$AV9)*100 -> 98.046121 | AF9: =AR9/MAX($AK9:$AV9)*100 -> 100 | ... AJ9: =AV9/MAX($AK9:$AV9)*100 -> 0 | AK9: {=_xlfn.IFS(AZ9=0,0,AZ9>0,(LOG(0.01*AZ9/10^-CD9)))} -> 0 | AL9: {=_xlfn.IFS(BA9=0,0,BA9>0,(LOG(0.01*BA9/10^-CE9)))} -> 6.8304923 | AM9: {=_xlfn.IFS(BB9=0,0,BB9>0,(LOG(0.01*BB9/10^-CF9)))} -> 6.7071688 | AN9: {=_xlfn.IFS(BC9=0,0,BC9>0,(LOG(0.01*BC9/10^-CG9)))} -> 6.9222062 | AO9: {=_xlfn.IFS(BD9=0,0,BD9>0,(LOG(0.01*BD9/10^-CH9)))} -> 6.807461 | AP9: {=_xlfn.IFS(BE9=0,0,BE9>0,(LOG(0.01*BE9/10^-CI9)))} -> 6.9991878 | AQ9: {=_xlfn.IFS(BF9=0,0,BF9>0,(LOG(0.01*BF9/10^-CJ9)))} -> 8.5401342 | AR9: {=_xlfn.IFS(BG9=0,0,BG9>0,(LOG(0.01*BG9/10^-CK9)))} -> 8.7103233 | ... AY9: {=_xlfn.IFS(BN9=0,0,BN9>0,(LOG(0.01*BN9/10^-CR9)))} -> 7.3206017 | AZ9: =IF(BO9="",0,100*BO9/MAX(BO:BO)) -> 0 | BA9: =IF(BP9="",0,100*BP9/MAX($BP:$BT)) -> 10.60455 | BB9: =IF(BQ9="",0,100*BQ9/MAX($BP:$BT)) -> 6.312026 | BC9: =IF(BR9="",0,100*BR9/MAX($BP:$BT)) -> 6.1830986 | BD9: =IF(BS9="",0,100*BS9/MAX($BP:$BT)) -> 5.6814735 | BE9: =IF(BT9="",0,100*BT9/MAX($BP:$BT)) -> 10.073673 | BF9: =IF(BU9="",0,100*BU9/MAX($BU:$BX)) -> 57.69447 | BG9: =IF(BV9="",0,100*BV9/MAX($BU:$BX)) -> 76.616682 | BH9: =IF(BW9="",0,100*BW9/MAX($BU:$BX)) -> 77.956888 | BI9: =IF(BX9="",0,100*BX9/MAX($BU:$BX)) -> 79.784442 | BJ9: =IF(BY9="",0,100*BY9/MAX($BY:$BZ)) -> 0 | BK9: =IF(BZ9="",0,100*BZ9/MAX($BY:$BZ)) -> 0 | BL9: =IF(CA9="",0,100*CA9/MAX($CA:$CC)) -> 29.879154 | BM9: =IF(CB9="",0,100*CB9/MAX($CA:$CC)) -> 22.836522 | BN9: =IF(CC9="",0,100*CC9/MAX($CA:$CC)) -> 31.376301 | BP9: 97.88 | BQ9: 58.26 | BR9: 57.07 | BS9: 52.44 | BT9: 92.98 | BU9: 615.6 | BV9: 817.5 | BW9: 831.8 | BX9: 851.3 | CA9: 890.1 | CB9: 680.3 | CC9: 934.7 | CE9: 7.805 | CF9: 7.907 | CG9: 8.131 | CH9: 8.053 | CI9: 7.996 | CJ9: 8.779 | CK9: 8.826 | CL9: 8.187 | CM9: 8.01 | CP9: 7.743 | CQ9: 7.841 | CR9: 7.824 | CS9: =IF(VLOOKUP($A9,'B-Ligands'!$A:$G,3,FALSE)="","",VLOOKUP($A9,'B-Ligands'!$A:$G,3,FALSE)) -> AVP | CT9: =IF(VLOOKUP($A9,'B-Ligands'!$A:$G,4,FALSE)="","",VLOOKUP($A9,'B-Ligands'!$A:$G,4,FALSE)) -> Vasopressin | CU9: 9.6057439 | CV9: 2.9288447 | CW9: 8.1434844 | CX9: 6.0507239 | CY9: 3.935063 | CZ9: 1.0479132 | DA9: 8.5510395 | DB9: 4.117783 | DC9: 6.1085796 | DD9: 5.6743723 | DE9: 17.867628 | DF9: 12.702031 | DG9: 9.0882481 | DH9: 3.8338979 | DI9: 5.6784866 | DJ9: =IF(BO9="",0,BO9/CU9) -> 0 | DK9: =IF(BP9="",0,BP9/CV9) -> 33.419321 | DL9: =IF(BQ9="",0,BQ9/CW9) -> 7.1541857 | DM9: =IF(BR9="",0,BR9/CX9) -> 9.4319292 | DN9: =IF(BS9="",0,BS9/CY9) -> 13.326343 | DO9: =IF(BT9="",0,BT9/CZ9) -> 88.728723 | DP9: =IF(BU9="",0,BU9/DA9) -> 71.991247 | DQ9: =IF(BV9="",0,BV9/DB9) -> 198.52916 | ... DX9: =IF(CC9="",0,CC9/DI9) -> 164.60372
A10: CCKAR | B10: 10.7554/eLife.74101 | C10: =IF(VLOOKUP($A10,'B-Ligands'!$A:$G,5,FALSE)="","",VLOOKUP($A10,'B-Ligands'!$A:$G,5,FALSE)) -> Guide To Pharmacology | D10: =IF(VLOOKUP($A10,'B-Ligands'!$A:$G,6,FALSE)="","",VLOOKUP($A10,'B-Ligands'!$A:$G,6,FALSE)) -> 864 | E10: =IF(VLOOKUP($A10,'B-Ligands'!$A:$G,7,FALSE)="","",VLOOKUP($A10,'B-Ligands'!$A:$G,7,FALSE)) -> Phys | F10: =IF(T10>0,1,"") -> 1 | G10: =IF(U10>0,1,"") -> 1 | H10: =IF(V10>0,1,"") -> 1 | I10: =IF(W10>0,1,"") -> 1 | J10: =COUNTIF(L10:O10,">0") -> 4 | K10: =SUBSTITUTE(INDEX(T$1:W$1,1,MATCH(MAX(T10:W10),T10:W10,0)),"-fam","") -> G12/13 | L10: =IF(T10=0,0,_xlfn.RANK.EQ(T10,$T10:$W10,0)) -> 4 | M10: =IF(U10=0,0,_xlfn.RANK.EQ(U10,$T10:$W10,0)) -> 3 | N10: =IF(V10=0,0,_xlfn.RANK.EQ(V10,$T10:$W10,0)) -> 2 | O10: =IF(W10=0,0,_xlfn.RANK.EQ(W10,$T10:$W10,0)) -> 1 | P10: =T10/MAX($T10:$W10)*100 -> 82.897919 | Q10: =U10/MAX($T10:$W10)*100 -> 87.589304 | R10: =V10/MAX($T10:$W10)*100 -> 99.29236 | S10: =W10/MAX($T10:$W10)*100 -> 100 | T10: =AK10 -> 8.0784279 | U10: =MAX(AL10:AP10) -> 8.5356048 | V10: =MAX(AQ10:AT10) -> 9.6760712 | W10: =MAX(AU10:AV10) -> 9.745031 | X10: =INDEX(AK$1:AV$1,1,MATCH(MAX(AK10:AV10),AK10:AV10,0)) -> G12 | Y10: =AK10/MAX($AK10:$AV10)*100 -> 82.897919 | Z10: =AL10/MAX($AK10:$AV10)*100 -> 86.510777 | AA10: =AM10/MAX($AK10:$AV10)*100 -> 84.477598 | AB10: =AN10/MAX($AK10:$AV10)*100 -> 87.589304 | AC10: =AO10/MAX($AK10:$AV10)*100 -> 86.751016 | AD10: =AP10/MAX($AK10:$AV10)*100 -> 79.980663 | AE10: =AQ10/MAX($AK10:$AV10)*100 -> 96.05764 | AF10: =AR10/MAX($AK10:$AV10)*100 -> 98.476207 | ... AJ10: =AV10/MAX($AK10:$AV10)*100 -> 94.283949 | AK10: {=_xlfn.IFS(AZ10=0,0,AZ10>0,(LOG(0.01*AZ10/10^-CD10)))} -> 8.0784279 | AL10: {=_xlfn.IFS(BA10=0,0,BA10>0,(LOG(0.01*BA10/10^-CE10)))} -> 8.430502 | AM10: {=_xlfn.IFS(BB10=0,0,BB10>0,(LOG(0.01*BB10/10^-CF10)))} -> 8.2323681 | AN10: {=_xlfn.IFS(BC10=0,0,BC10>0,(LOG(0.01*BC10/10^-CG10)))} -> 8.5356048 | AO10: {=_xlfn.IFS(BD10=0,0,BD10>0,(LOG(0.01*BD10/10^-CH10)))} -> 8.4539134 | AP10: {=_xlfn.IFS(BE10=0,0,BE10>0,(LOG(0.01*BE10/10^-CI10)))} -> 7.7941404 | AQ10: {=_xlfn.IFS(BF10=0,0,BF10>0,(LOG(0.01*BF10/10^-CJ10)))} -> 9.3608468 | AR10: {=_xlfn.IFS(BG10=0,0,BG10>0,(LOG(0.01*BG10/10^-CK10)))} -> 9.5965369 | ... AY10: {=_xlfn.IFS(BN10=0,0,BN10>0,(LOG(0.01*BN10/10^-CR10)))} -> 8.4287731 | AZ10: =IF(BO10="",0,100*BO10/MAX(BO:BO)) -> 39.941825 | BA10: =IF(BP10="",0,100*BP10/MAX($BP:$BT)) -> 54.387866 | BB10: =IF(BQ10="",0,100*BQ10/MAX($BP:$BT)) -> 24.008667 | BC10: =IF(BR10="",0,100*BR10/MAX($BP:$BT)) -> 25.503792 | BD10: =IF(BS10="",0,100*BS10/MAX($BP:$BT)) -> 26.056338 | BE10: =IF(BT10="",0,100*BT10/MAX($BP:$BT)) -> 18.244854 | BF10: =IF(BU10="",0,100*BU10/MAX($BU:$BX)) -> 42.839738 | BG10: =IF(BV10="",0,100*BV10/MAX($BU:$BX)) -> 51.349578 | BH10: =IF(BW10="",0,100*BW10/MAX($BU:$BX)) -> 56.373008 | BI10: =IF(BX10="",0,100*BX10/MAX($BU:$BX)) -> 79.512652 | BJ10: =IF(BY10="",0,100*BY10/MAX($BY:$BZ)) -> 13.336165 | BK10: =IF(BZ10="",0,100*BZ10/MAX($BY:$BZ)) -> 100 | BL10: =IF(CA10="",0,100*CA10/MAX($CA:$CC)) -> 46.12286 | BM10: =IF(CB10="",0,100*CB10/MAX($CA:$CC)) -> 27.593152 | BN10: =IF(CC10="",0,100*CC10/MAX($CA:$CC)) -> 51.023834 | BO10: 26.09 | BP10: 502 | BQ10: 221.6 | BR10: 235.4 | BS10: 240.5 | BT10: 168.4 | BU10: 457.1 | BV10: 547.9 | BW10: 601.5 | BX10: 848.4 | BY10: 94.18 | BZ10: 706.2 | CA10: 1374 | CB10: 822 | CC10: 1520 | CD10: 8.477 | CE10: 8.695 | CF10: 8.852 | CG10: 9.129 | CH10: 9.038 | CI10: 8.533 | CJ10: 9.729 | CK10: 9.886 | CL10: 9.925 | CM10: 8.911 | CN10: 10.62 | CO10: 9.188 | CP10: 8.329 | CQ10: 7.919 | CR10: 8.721 | CS10: =IF(VLOOKUP($A10,'B-Ligands'!$A:$G,3,FALSE)="","",VLOOKUP($A10,'B-Ligands'!$A:$G,3,FALSE)) -> CCK-8 | CT10: =IF(VLOOKUP($A10,'B-Ligands'!$A:$G,4,FALSE)="","",VLOOKUP($A10,'B-Ligands'!$A:$G,4,FALSE)) -> Cholecystokinin 8 | CU10: 6.1193556 | CV10: 10.562021 | CW10: 2.2564256 | CX10: 24.717211 | CY10: 17.499667 | CZ10: 2.3220149 | DA10: 2.8129304 | DB10: 2.6731684 | DC10: 4.6772703 | DD10: 3.3899128 | DE10: 13.779842 | DF10: 15.914174 | DG10: 19.057834 | DH10: 1.9496295 | DI10: 10.099421 | DJ10: =IF(BO10="",0,BO10/CU10) -> 4.2635208 | DK10: =IF(BP10="",0,BP10/CV10) -> 47.528783 | DL10: =IF(BQ10="",0,BQ10/CW10) -> 98.208422 | DM10: =IF(BR10="",0,BR10/CX10) -> 9.5237283 | DN10: =IF(BS10="",0,BS10/CY10) -> 13.743118 | DO10: =IF(BT10="",0,BT10/CZ10) -> 72.523221 | DP10: =IF(BU10="",0,BU10/DA10) -> 162.49958 | DQ10: =IF(BV10="",0,BV10/DB10) -> 204.96277 | ... DX10: =IF(CC10="",0,CC10/DI10) -> 150.50368
A11: 5HT1A | B11: 10.7554/eLife.74101 | C11: =IF(VLOOKUP($A11,'B-Ligands'!$A:$G,5,FALSE)="","",VLOOKUP($A11,'B-Ligands'!$A:$G,5,FALSE)) -> Guide To Pharmacology | D11: =IF(VLOOKUP($A11,'B-Ligands'!$A:$G,6,FALSE)="","",VLOOKUP($A11,'B-Ligands'!$A:$G,6,FALSE)) -> 5 | E11: =IF(VLOOKUP($A11,'B-Ligands'!$A:$G,7,FALSE)="","",VLOOKUP($A11,'B-Ligands'!$A:$G,7,FALSE)) -> Phys | F11: =IF(T11>0,1,"") | G11: =IF(U11>0,1,"") -> 1 | H11: =IF(V11>0,1,"") -> 1 | I11: =IF(W11>0,1,"") | J11: =COUNTIF(L11:O11,">0") -> 2 | K11: =SUBSTITUTE(INDEX(T$1:W$1,1,MATCH(MAX(T11:W11),T11:W11,0)),"-fam","") -> Gi/o | L11: =IF(T11=0,0,_xlfn.RANK.EQ(T11,$T11:$W11,0)) -> 0 | M11: =IF(U11=0,0,_xlfn.RANK.EQ(U11,$T11:$W11,0)) -> 1 | N11: =IF(V11=0,0,_xlfn.RANK.EQ(V11,$T11:$W11,0)) -> 2 | O11: =IF(W11=0,0,_xlfn.RANK.EQ(W11,$T11:$W11,0)) -> 0 | P11: =T11/MAX($T11:$W11)*100 -> 0 | Q11: =U11/MAX($T11:$W11)*100 -> 100 | R11: =V11/MAX($T11:$W11)*100 -> 81.193693 | S11: =W11/MAX($T11:$W11)*100 -> 0 | T11: =AK11 -> 0 | U11: =MAX(AL11:AP11) -> 8.2691545 | V11: =MAX(AQ11:AT11) -> 6.7140319 | W11: =MAX(AU11:AV11) -> 0 | X11: =INDEX(AK$1:AV$1,1,MATCH(MAX(AK11:AV11),AK11:AV11,0)) -> GoB | Y11: =AK11/MAX($AK11:$AV11)*100 -> 0 | Z11: =AL11/MAX($AK11:$AV11)*100 -> 92.144273 | AA11: =AM11/MAX($AK11:$AV11)*100 -> 85.08465 | AB11: =AN11/MAX($AK11:$AV11)*100 -> 96.602892 | AC11: =AO11/MAX($AK11:$AV11)*100 -> 100 | AD11: =AP11/MAX($AK11:$AV11)*100 -> 95.66883 | AE11: =AQ11/MAX($AK11:$AV11)*100 -> 0 | AF11: =AR11/MAX($AK11:$AV11)*100 -> 0 | ... AJ11: =AV11/MAX($AK11:$AV11)*100 -> 0 | AK11: {=_xlfn.IFS(AZ11=0,0,AZ11>0,(LOG(0.01*AZ11/10^-CD11)))} -> 0 | AL11: {=_xlfn.IFS(BA11=0,0,BA11>0,(LOG(0.01*BA11/10^-CE11)))} -> 7.6195523 | AM11: {=_xlfn.IFS(BB11=0,0,BB11>0,(LOG(0.01*BB11/10^-CF11)))} -> 7.0357811 | AN11: {=_xlfn.IFS(BC11=0,0,BC11>0,(LOG(0.01*BC11/10^-CG11)))} -> 7.9882424 | AO11: {=_xlfn.IFS(BD11=0,0,BD11>0,(LOG(0.01*BD11/10^-CH11)))} -> 8.2691545 | AP11: {=_xlfn.IFS(BE11=0,0,BE11>0,(LOG(0.01*BE11/10^-CI11)))} -> 7.9110034 | AQ11: {=_xlfn.IFS(BF11=0,0,BF11>0,(LOG(0.01*BF11/10^-CJ11)))} -> 0 | AR11: {=_xlfn.IFS(BG11=0,0,BG11>0,(LOG(0.01*BG11/10^-CK11)))} -> 0 | ... AY11: {=_xlfn.IFS(BN11=0,0,BN11>0,(LOG(0.01*BN11/10^-CR11)))} -> 5.4232844 | AZ11: =IF(BO11="",0,100*BO11/MAX(BO:BO)) -> 0 | BA11: =IF(BP11="",0,100*BP11/MAX($BP:$BT)) -> 68.320693 | BB11: =IF(BQ11="",0,100*BQ11/MAX($BP:$BT)) -> 41.094258 | BC11: =IF(BR11="",0,100*BR11/MAX($BP:$BT)) -> 23.726977 | BD11: =IF(BS11="",0,100*BS11/MAX($BP:$BT)) -> 36.153846 | BE11: =IF(BT11="",0,100*BT11/MAX($BP:$BT)) -> 20.84507 | BF11: =IF(BU11="",0,100*BU11/MAX($BU:$BX)) -> 0 | BG11: =IF(BV11="",0,100*BV11/MAX($BU:$BX)) -> 0 | BH11: =IF(BW11="",0,100*BW11/MAX($BU:$BX)) -> 13.880037 | BI11: =IF(BX11="",0,100*BX11/MAX($BU:$BX)) -> 75.688847 | BJ11: =IF(BY11="",0,100*BY11/MAX($BY:$BZ)) -> 0 | BK11: =IF(BZ11="",0,100*BZ11/MAX($BY:$BZ)) -> 0 | BL11: =IF(CA11="",0,100*CA11/MAX($CA:$CC)) -> 3.1910037 | BM11: =IF(CB11="",0,100*CB11/MAX($CA:$CC)) -> 3.1628063 | BN11: =IF(CC11="",0,100*CC11/MAX($CA:$CC)) -> 6.0993622 | BP11: 630.6 | BQ11: 379.3 | BR11: 219 | BS11: 333.7 | BT11: 192.4 | BW11: 148.1 | BX11: 807.6 | CA11: 95.06 | CB11: 94.22 | CC11: 181.7 | CE11: 7.785 | CF11: 7.422 | CG11: 8.613 | CH11: 8.711 | CI11: 8.592 | CL11: 6.215 | CM11: 6.835 | CP11: 6.579 | CQ11: 6.477 | CR11: 6.638 | CS11: =IF(VLOOKUP($A11,'B-Ligands'!$A:$G,3,FALSE)="","",VLOOKUP($A11,'B-Ligands'!$A:$G,3,FALSE)) | CT11: =IF(VLOOKUP($A11,'B-Ligands'!$A:$G,4,FALSE)="","",VLOOKUP($A11,'B-Ligands'!$A:$G,4,FALSE)) -> Serotonin | CU11: 12.506612 | CV11: 26.68292 | CW11: 12.127683 | CX11: 4.0158107 | CY11: 18.473651 | CZ11: 30.179716 | DA11: 30.407166 | DB11: 18.759059 | DC11: 8.5027387 | DD11: 22.39184 | DE11: 3.9936236 | DF11: 0.60011222 | DG11: 14.510347 | DH11: 44.33622 | DI11: 51.685651 | DJ11: =IF(BO11="",0,BO11/CU11) -> 0 | DK11: =IF(BP11="",0,BP11/CV11) -> 23.633095 | DL11: =IF(BQ11="",0,BQ11/CW11) -> 31.275555 | DM11: =IF(BR11="",0,BR11/CX11) -> 54.534443 | DN11: =IF(BS11="",0,BS11/CY11) -> 18.063565 | DO11: =IF(BT11="",0,BT11/CZ11) -> 6.3751429 | DP11: =IF(BU11="",0,BU11/DA11) -> 0 | DQ11: =IF(BV11="",0,BV11/DB11) -> 0 | ... DX11: =IF(CC11="",0,CC11/DI11) -> 3.5154825
A12: PE2R1 | B12: 10.7554/eLife.74101 | C12: =IF(VLOOKUP($A12,'B-Ligands'!$A:$G,5,FALSE)="","",VLOOKUP($A12,'B-Ligands'!$A:$G,5,FALSE)) -> Guide To Pharmacology | D12: =IF(VLOOKUP($A12,'B-Ligands'!$A:$G,6,FALSE)="","",VLOOKUP($A12,'B-Ligands'!$A:$G,6,FALSE)) -> 1883 | E12: =IF(VLOOKUP($A12,'B-Ligands'!$A:$G,7,FALSE)="","",VLOOKUP($A12,'B-Ligands'!$A:$G,7,FALSE)) -> Phys | F12: =IF(T12>0,1,"") | G12: =IF(U12>0,1,"") -> 1 | H12: =IF(V12>0,1,"") -> 1 | I12: =IF(W12>0,1,"") -> 1 | J12: =COUNTIF(L12:O12,">0") -> 3 | K12: =SUBSTITUTE(INDEX(T$1:W$1,1,MATCH(MAX(T12:W12),T12:W12,0)),"-fam","") -> Gq/11 | L12: =IF(T12=0,0,_xlfn.RANK.EQ(T12,$T12:$W12,0)) -> 0 | M12: =IF(U12=0,0,_xlfn.RANK.EQ(U12,$T12:$W12,0)) -> 3 | N12: =IF(V12=0,0,_xlfn.RANK.EQ(V12,$T12:$W12,0)) -> 1 | O12: =IF(W12=0,0,_xlfn.RANK.EQ(W12,$T12:$W12,0)) -> 2 | P12: =T12/MAX($T12:$W12)*100 -> 0 | Q12: =U12/MAX($T12:$W12)*100 -> 72.731777 | R12: =V12/MAX($T12:$W12)*100 -> 100 | S12: =W12/MAX($T12:$W12)*100 -> 93.498725 | T12: =AK12 -> 0 | U12: =MAX(AL12:AP12) -> 6.6700809 | V12: =MAX(AQ12:AT12) -> 9.1707933 | W12: =MAX(AU12:AV12) -> 8.5745748 | X12: =INDEX(AK$1:AV$1,1,MATCH(MAX(AK12:AV12),AK12:AV12,0)) -> G15 | Y12: =AK12/MAX($AK12:$AV12)*100 -> 0 | Z12: =AL12/MAX($AK12:$AV12)*100 -> 56.831498 | AA12: =AM12/MAX($AK12:$AV12)*100 -> 64.139463 | AB12: =AN12/MAX($AK12:$AV12)*100 -> 72.731777 | AC12: =AO12/MAX($AK12:$AV12)*100 -> 67.454852 | AD12: =AP12/MAX($AK12:$AV12)*100 -> 0 | AE12: =AQ12/MAX($AK12:$AV12)*100 -> 83.662377 | AF12: =AR12/MAX($AK12:$AV12)*100 -> 84.579909 | ... AJ12: =AV12/MAX($AK12:$AV12)*100 -> 76.100183 | AK12: {=_xlfn.IFS(AZ12=0,0,AZ12>0,(LOG(0.01*AZ12/10^-CD12)))} -> 0 | AL12: {=_xlfn.IFS(BA12=0,0,BA12>0,(LOG(0.01*BA12/10^-CE12)))} -> 5.2118992 | AM12: {=_xlfn.IFS(BB12=0,0,BB12>0,(LOG(0.01*BB12/10^-CF12)))} -> 5.8820976 | AN12: {=_xlfn.IFS(BC12=0,0,BC12>0,(LOG(0.01*BC12/10^-CG12)))} -> 6.6700809 | AO12: {=_xlfn.IFS(BD12=0,0,BD12>0,(LOG(0.01*BD12/10^-CH12)))} -> 6.1861451 | AP12: {=_xlfn.IFS(BE12=0,0,BE12>0,(LOG(0.01*BE12/10^-CI12)))} -> 0 | AQ12: {=_xlfn.IFS(BF12=0,0,BF12>0,(LOG(0.01*BF12/10^-CJ12)))} -> 7.6725036 | AR12: {=_xlfn.IFS(BG12=0,0,BG12>0,(LOG(0.01*BG12/10^-CK12)))} -> 7.7566486 | ... AY12: {=_xlfn.IFS(BN12=0,0,BN12>0,(LOG(0.01*BN12/10^-CR12)))} -> 0 | AZ12: =IF(BO12="",0,100*BO12/MAX(BO:BO)) -> 0 | BA12: =IF(BP12="",0,100*BP12/MAX($BP:$BT)) -> 6.0520043 | BB12: =IF(BQ12="",0,100*BQ12/MAX($BP:$BT)) -> 3.2816901 | BC12: =IF(BR12="",0,100*BR12/MAX($BP:$BT)) -> 4.6782232 | BD12: =IF(BS12="",0,100*BS12/MAX($BP:$BT)) -> 5.3228602 | BE12: =IF(BT12="",0,100*BT12/MAX($BP:$BT)) -> 0 | BF12: =IF(BU12="",0,100*BU12/MAX($BU:$BX)) -> 22.464855 | BG12: =IF(BV12="",0,100*BV12/MAX($BU:$BX)) -> 30.384255 | BH12: =IF(BW12="",0,100*BW12/MAX($BU:$BX)) -> 14.75164 | BI12: =IF(BX12="",0,100*BX12/MAX($BU:$BX)) -> 75.47329 | BJ12: =IF(BY12="",0,100*BY12/MAX($BY:$BZ)) -> 11.496743 | BK12: =IF(BZ12="",0,100*BZ12/MAX($BY:$BZ)) -> 8.749646 | BL12: =IF(CA12="",0,100*CA12/MAX($CA:$CC)) -> 0 | BM12: =IF(CB12="",0,100*CB12/MAX($CA:$CC)) -> 1.1161464 | BN12: =IF(CC12="",0,100*CC12/MAX($CA:$CC)) -> 0 | BP12: 55.86 | BQ12: 30.29 | BR12: 43.18 | BS12: 49.13 | BU12: 239.7 | BV12: 324.2 | BW12: 157.4 | BX12: 805.3 | BY12: 81.19 | BZ12: 61.79 | CB12: 33.25 | CE12: 6.43 | CF12: 7.366 | CG12: 8 | CH12: 7.46 | CJ12: 8.321 | CK12: 8.274 | CL12: 7.946 | CM12: 9.293 | CN12: 9.514 | CO12: 8.037 | CQ12: 7.407 | CS12: =IF(VLOOKUP($A12,'B-Ligands'!$A:$G,3,FALSE)="","",VLOOKUP($A12,'B-Ligands'!$A:$G,3,FALSE)) -> PGE2 | CT12: =IF(VLOOKUP($A12,'B-Ligands'!$A:$G,4,FALSE)="","",VLOOKUP($A12,'B-Ligands'!$A:$G,4,FALSE)) -> Prostaglandin E2 | CU12: 12.993482 | CV12: 25.430388 | CW12: 7.8388755 | CX12: 13.47391 | CY12: 15.692677 | CZ12: 3.8814959 | DA12: 13.783701 | DB12: 15.561459 | DC12: 14.230644 | DD12: 11.137744 | DE12: 22.31171 | DF12: 18.872758 | DG12: 11.455748 | DH12: 10.679613 | DI12: 20.386431 | DJ12: =IF(BO12="",0,BO12/CU12) -> 0 | DK12: =IF(BP12="",0,BP12/CV12) -> 2.1965847 | DL12: =IF(BQ12="",0,BQ12/CW12) -> 3.8640747 | DM12: =IF(BR12="",0,BR12/CX12) -> 3.2047119 | DN12: =IF(BS12="",0,BS12/CY12) -> 3.1307596 | DO12: =IF(BT12="",0,BT12/CZ12) -> 0 | DP12: =IF(BU12="",0,BU12/DA12) -> 17.390104 | DQ12: =IF(BV12="",0,BV12/DB12) -> 20.833523 | ... DX12: =IF(CC12="",0,CC12/DI12) -> 0
A13: 5HT2A | B13: 10.7554/eLife.74101 | C13: =IF(VLOOKUP($A13,'B-Ligands'!$A:$G,5,FALSE)="","",VLOOKUP($A13,'B-Ligands'!$A:$G,5,FALSE)) -> Guide To Pharmacology | D13: =IF(VLOOKUP($A13,'B-Ligands'!$A:$G,6,FALSE)="","",VLOOKUP($A13,'B-Ligands'!$A:$G,6,FALSE)) -> 5 | E13: =IF(VLOOKUP($A13,'B-Ligands'!$A:$G,7,FALSE)="","",VLOOKUP($A13,'B-Ligands'!$A:$G,7,FALSE)) -> Phys | F13: =IF(T13>0,1,"") | G13: =IF(U13>0,1,"") -> 1 | H13: =IF(V13>0,1,"") -> 1 | I13: =IF(W13>0,1,"") | J13: =COUNTIF(L13:O13,">0") -> 2 | K13: =SUBSTITUTE(INDEX(T$1:W$1,1,MATCH(MAX(T13:W13),T13:W13,0)),"-fam","") -> Gq/11 | L13: =IF(T13=0,0,_xlfn.RANK.EQ(T13,$T13:$W13,0)) -> 0 | M13: =IF(U13=0,0,_xlfn.RANK.EQ(U13,$T13:$W13,0)) -> 2 | N13: =IF(V13=0,0,_xlfn.RANK.EQ(V13,$T13:$W13,0)) -> 1 | O13: =IF(W13=0,0,_xlfn.RANK.EQ(W13,$T13:$W13,0)) -> 0 | P13: =T13/MAX($T13:$W13)*100 -> 0 | Q13: =U13/MAX($T13:$W13)*100 -> 77.306567 | R13: =V13/MAX($T13:$W13)*100 -> 100 | S13: =W13/MAX($T13:$W13)*100 -> 0 | T13: =AK13 -> 0 | U13: =MAX(AL13:AP13) -> 6.6614875 | V13: =MAX(AQ13:AT13) -> 8.616975 | W13: =MAX(AU13:AV13) -> 0 | X13: =INDEX(AK$1:AV$1,1,MATCH(MAX(AK13:AV13),AK13:AV13,0)) -> G14 | Y13: =AK13/MAX($AK13:$AV13)*100 -> 0 | Z13: =AL13/MAX($AK13:$AV13)*100 -> 67.943945 | AA13: =AM13/MAX($AK13:$AV13)*100 -> 63.29923 | AB13: =AN13/MAX($AK13:$AV13)*100 -> 62.258112 | AC13: =AO13/MAX($AK13:$AV13)*100 -> 66.395032 | AD13: =AP13/MAX($AK13:$AV13)*100 -> 77.306567 | AE13: =AQ13/MAX($AK13:$AV13)*100 -> 97.706871 | AF13: =AR13/MAX($AK13:$AV13)*100 -> 98.806257 | ... AJ13: =AV13/MAX($AK13:$AV13)*100 -> 0 | AK13: {=_xlfn.IFS(AZ13=0,0,AZ13>0,(LOG(0.01*AZ13/10^-CD13)))} -> 0 | AL13: {=_xlfn.IFS(BA13=0,0,BA13>0,(LOG(0.01*BA13/10^-CE13)))} -> 5.8547128 | AM13: {=_xlfn.IFS(BB13=0,0,BB13>0,(LOG(0.01*BB13/10^-CF13)))} -> 5.4544788 | AN13: {=_xlfn.IFS(BC13=0,0,BC13>0,(LOG(0.01*BC13/10^-CG13)))} -> 5.364766 | AO13: {=_xlfn.IFS(BD13=0,0,BD13>0,(LOG(0.01*BD13/10^-CH13)))} -> 5.7212433 | AP13: {=_xlfn.IFS(BE13=0,0,BE13>0,(LOG(0.01*BE13/10^-CI13)))} -> 6.6614875 | AQ13: {=_xlfn.IFS(BF13=0,0,BF13>0,(LOG(0.01*BF13/10^-CJ13)))} -> 8.4193767 | AR13: {=_xlfn.IFS(BG13=0,0,BG13>0,(LOG(0.01*BG13/10^-CK13)))} -> 8.5141104 | ... AY13: {=_xlfn.IFS(BN13=0,0,BN13>0,(LOG(0.01*BN13/10^-CR13)))} -> 6.4452439 | AZ13: =IF(BO13="",0,100*BO13/MAX(BO:BO)) -> 0 | BA13: =IF(BP13="",0,100*BP13/MAX($BP:$BT)) -> 9.0097508 | BB13: =IF(BQ13="",0,100*BQ13/MAX($BP:$BT)) -> 3.5438787 | BC13: =IF(BR13="",0,100*BR13/MAX($BP:$BT)) -> 3.6793066 | BD13: =IF(BS13="",0,100*BS13/MAX($BP:$BT)) -> 6.3131094 | BE13: =IF(BT13="",0,100*BT13/MAX($BP:$BT)) -> 16.348862 | BF13: =IF(BU13="",0,100*BU13/MAX($BU:$BX)) -> 13.720712 | BG13: =IF(BV13="",0,100*BV13/MAX($BU:$BX)) -> 10.449859 | BH13: =IF(BW13="",0,100*BW13/MAX($BU:$BX)) -> 24.489222 | BI13: =IF(BX13="",0,100*BX13/MAX($BU:$BX)) -> 72.680412 | BJ13: =IF(BY13="",0,100*BY13/MAX($BY:$BZ)) -> 0 | BK13: =IF(BZ13="",0,100*BZ13/MAX($BY:$BZ)) -> 0 | BL13: =IF(CA13="",0,100*CA13/MAX($CA:$CC)) -> 17.391742 | BM13: =IF(CB13="",0,100*CB13/MAX($CA:$CC)) -> 11.450151 | BN13: =IF(CC13="",0,100*CC13/MAX($CA:$CC)) -> 26.136287 | BP13: 83.16 | BQ13: 32.71 | BR13: 33.96 | BS13: 58.27 | BT13: 150.9 | BU13: 146.4 | BV13: 111.5 | BW13: 261.3 | BX13: 775.5 | CA13: 518.1 | CB13: 341.1 | CC13: 778.6 | CE13: 6.9 | CF13: 6.905 | CG13: 6.799 | CH13: 6.921 | CI13: 7.448 | CJ13: 9.282 | CK13: 9.495 | CL13: 9.228 | CM13: 8.123 | CP13: 6.709 | CQ13: 6.963 | CR13: 7.028 | CS13: =IF(VLOOKUP($A13,'B-Ligands'!$A:$G,3,FALSE)="","",VLOOKUP($A13,'B-Ligands'!$A:$G,3,FALSE)) | CT13: =IF(VLOOKUP($A13,'B-Ligands'!$A:$G,4,FALSE)="","",VLOOKUP($A13,'B-Ligands'!$A:$G,4,FALSE)) -> Serotonin | CU13: 8.673395 | CV13: 32.727048 | CW13: 22.786429 | CX13: 23.615518 | CY13: 11.948034 | CZ13: 69.129318 | DA13: 15.497954 | DB13: 9.9817672 | DC13: 11.901058 | DD13: 8.8399396 | DE13: 29.325535 | DF13: 39.242816 | DG13: 30.695073 | DH13: 13.731355 | DI13: 6.0605655 | DJ13: =IF(BO13="",0,BO13/CU13) -> 0 | DK13: =IF(BP13="",0,BP13/CV13) -> 2.5410175 | DL13: =IF(BQ13="",0,BQ13/CW13) -> 1.4355036 | DM13: =IF(BR13="",0,BR13/CX13) -> 1.4380375 | DN13: =IF(BS13="",0,BS13/CY13) -> 4.8769531 | DO13: =IF(BT13="",0,BT13/CZ13) -> 2.1828655 | DP13: =IF(BU13="",0,BU13/DA13) -> 9.4464081 | DQ13: =IF(BV13="",0,BV13/DB13) -> 11.170367 | ... DX13: =IF(CC13="",0,CC13/DI13) -> 128.46986
A14: DRD5 | B14: 10.7554/eLife.74101 | C14: =IF(VLOOKUP($A14,'B-Ligands'!$A:$G,5,FALSE)="","",VLOOKUP($A14,'B-Ligands'!$A:$G,5,FALSE)) -> Guide To Pharmacology | D14: =IF(VLOOKUP($A14,'B-Ligands'!$A:$G,6,FALSE)="","",VLOOKUP($A14,'B-Ligands'!$A:$G,6,FALSE)) -> 940 | E14: =IF(VLOOKUP($A14,'B-Ligands'!$A:$G,7,FALSE)="","",VLOOKUP($A14,'B-Ligands'!$A:$G,7,FALSE)) -> Phys | F14: =IF(T14>0,1,"") -> 1 | G14: =IF(U14>0,1,"") -> 1 | H14: =IF(V14>0,1,"") -> 1 | I14: =IF(W14>0,1,"") | J14: =COUNTIF(L14:O14,">0") -> 3 | K14: =SUBSTITUTE(INDEX(T$1:W$1,1,MATCH(MAX(T14:W14),T14:W14,0)),"-fam","") -> Gs | L14: =IF(T14=0,0,_xlfn.RANK.EQ(T14,$T14:$W14,0)) -> 1 | M14: =IF(U14=0,0,_xlfn.RANK.EQ(U14,$T14:$W14,0)) -> 3 | N14: =IF(V14=0,0,_xlfn.RANK.EQ(V14,$T14:$W14,0)) -> 2 | O14: =IF(W14=0,0,_xlfn.RANK.EQ(W14,$T14:$W14,0)) -> 0 | P14: =T14/MAX($T14:$W14)*100 -> 100 | Q14: =U14/MAX($T14:$W14)*100 -> 69.540233 | R14: =V14/MAX($T14:$W14)*100 -> 91.376643 | S14: =W14/MAX($T14:$W14)*100 -> 0 | T14: =AK14 -> 8.4421832 | U14: =MAX(AL14:AP14) -> 5.8707138 | V14: =MAX(AQ14:AT14) -> 7.7141836 | W14: =MAX(AU14:AV14) -> 0 | X14: =INDEX(AK$1:AV$1,1,MATCH(MAX(AK14:AV14),AK14:AV14,0)) -> GsL | Y14: =AK14/MAX($AK14:$AV14)*100 -> 100 | Z14: =AL14/MAX($AK14:$AV14)*100 -> 60.39445 | AA14: =AM14/MAX($AK14:$AV14)*100 -> 54.665101 | AB14: =AN14/MAX($AK14:$AV14)*100 -> 0 | AC14: =AO14/MAX($AK14:$AV14)*100 -> 69.540233 | AD14: =AP14/MAX($AK14:$AV14)*100 -> 0 | AE14: =AQ14/MAX($AK14:$AV14)*100 -> 0 | AF14: =AR14/MAX($AK14:$AV14)*100 -> 0 | ... AJ14: =AV14/MAX($AK14:$AV14)*100 -> 0 | AK14: {=_xlfn.IFS(AZ14=0,0,AZ14>0,(LOG(0.01*AZ14/10^-CD14)))} -> 8.4421832 | AL14: {=_xlfn.IFS(BA14=0,0,BA14>0,(LOG(0.01*BA14/10^-CE14)))} -> 5.0986101 | AM14: {=_xlfn.IFS(BB14=0,0,BB14>0,(LOG(0.01*BB14/10^-CF14)))} -> 4.6149279 | AN14: {=_xlfn.IFS(BC14=0,0,BC14>0,(LOG(0.01*BC14/10^-CG14)))} -> 0 | AO14: {=_xlfn.IFS(BD14=0,0,BD14>0,(LOG(0.01*BD14/10^-CH14)))} -> 5.8707138 | AP14: {=_xlfn.IFS(BE14=0,0,BE14>0,(LOG(0.01*BE14/10^-CI14)))} -> 0 | AQ14: {=_xlfn.IFS(BF14=0,0,BF14>0,(LOG(0.01*BF14/10^-CJ14)))} -> 0 | AR14: {=_xlfn.IFS(BG14=0,0,BG14>0,(LOG(0.01*BG14/10^-CK14)))} -> 0 | ... AY14: {=_xlfn.IFS(BN14=0,0,BN14>0,(LOG(0.01*BN14/10^-CR14)))} -> 5.9200227 | AZ14: =IF(BO14="",0,100*BO14/MAX(BO:BO)) -> 76.240049 | BA14: =IF(BP14="",0,100*BP14/MAX($BP:$BT)) -> 2.2264355 | BB14: =IF(BQ14="",0,100*BQ14/MAX($BP:$BT)) -> 2.0985915 | BC14: =IF(BR14="",0,100*BR14/MAX($BP:$BT)) -> 0 | BD14: =IF(BS14="",0,100*BS14/MAX($BP:$BT)) -> 10.561213 | BE14: =IF(BT14="",0,100*BT14/MAX($BP:$BT)) -> 0 | BF14: =IF(BU14="",0,100*BU14/MAX($BU:$BX)) -> 0 | BG14: =IF(BV14="",0,100*BV14/MAX($BU:$BX)) -> 0 | BH14: =IF(BW14="",0,100*BW14/MAX($BU:$BX)) -> 0 | BI14: =IF(BX14="",0,100*BX14/MAX($BU:$BX)) -> 72.474227 | BJ14: =IF(BY14="",0,100*BY14/MAX($BY:$BZ)) -> 0 | BK14: =IF(BZ14="",0,100*BZ14/MAX($BY:$BZ)) -> 0 | BL14: =IF(CA14="",0,100*CA14/MAX($CA:$CC)) -> 4.0147701 | BM14: =IF(CB14="",0,100*CB14/MAX($CA:$CC)) -> 8.9157435 | BN14: =IF(CC14="",0,100*CC14/MAX($CA:$CC)) -> 9.5065458 | BO14: 49.8 | BP14: 20.55 | BQ14: 19.37 | BS14: 97.48 | BX14: 773.3 | CA14: 119.6 | CB14: 265.6 | CC14: 283.2 | CD14: 8.56 | CE14: 6.751 | CF14: 6.293 | CH14: 6.847 | CM14: 7.854 | CP14: 6.753 | CQ14: 6.691 | CR14: 6.942 | CS14: =IF(VLOOKUP($A14,'B-Ligands'!$A:$G,3,FALSE)="","",VLOOKUP($A14,'B-Ligands'!$A:$G,3,FALSE)) | CT14: =IF(VLOOKUP($A14,'B-Ligands'!$A:$G,4,FALSE)="","",VLOOKUP($A14,'B-Ligands'!$A:$G,4,FALSE)) -> Dopamine | CU14: 6.4006713 | CV14: 9.6036036 | CW14: 11.44538 | CX14: 0.86675892 | CY14: 6.6066699 | CZ14: 8.9801512 | DA14: 6.5463229 | DB14: 20.832348 | DC14: 9.9786358 | DD14: 20.96496 | DE14: 32.528925 | DF14: 18.529044 | DG14: 16.969528 | DH14: 22.567238 | DI14: 10.575858 | DJ14: =IF(BO14="",0,BO14/CU14) -> 7.7804339 | DK14: =IF(BP14="",0,BP14/CV14) -> 2.1398218 | DL14: =IF(BQ14="",0,BQ14/CW14) -> 1.6923859 | DM14: =IF(BR14="",0,BR14/CX14) -> 0 | DN14: =IF(BS14="",0,BS14/CY14) -> 14.754786 | DO14: =IF(BT14="",0,BT14/CZ14) -> 0 | DP14: =IF(BU14="",0,BU14/DA14) -> 0 | DQ14: =IF(BV14="",0,BV14/DB14) -> 0 | ... DX14: =IF(CC14="",0,CC14/DI14) -> 26.777969
